Workbook

Sheet 總覽
B2: ★ 波段股價預估試算 — 使用說明
B4: 用途:進場前檢核個股的基本面、籌碼面與估值。於「股價預估」頁 E1 輸入股票代號,由估值鏈推算預估EPS與目標價。
B5: 估值鏈:近月營收×3 → 預估季營收 → ×毛利率 − 營業費用 + 業外 → ×(1−稅率) → 預估稅後淨利 ÷ 股本 → 預估EPS × 高/中/低本益比 → 目標價
B6: 注意:本檔原為 Google Sheets,IMPORTHTML 自動抓取功能在 Excel 已失效,各頁資料為 2026/08/14 快照。要更新資料或換股票時,請直接請 Claude 上網抓官方最新資料填入。
B8: 分類 | C8: 分頁 | D8: 用途 | E8: 原資料來源
B9: 🟡 儀表板 | C9: 股價預估 | D9: 主儀表板:輸入代號→訊號燈+估值鏈+預估EPS+目標價+股利 | E9: 彙整各分頁
B10: 🔵 基本面 | C10: 股票資訊 | D10: 個股基本資料:股價、股本、市值、Beta、財報/營收發布日、ETF持股 | E10: 富邦證券
B11: 🔵 基本面 | C11: 營收 | D11: 月營收與長短期年增率訊號 | E11: 富邦證券
B12: 🔵 基本面 | C12: 毛利率&業外 | D12: 季度獲利能力、業外占比、毛利率標準差通道 | E12: 富邦證券
B13: 🔵 基本面 | C13: 營業費用 | D13: 損益表季度拆解(累計→單季)、稅率、費用率、週轉天數 | E13: money-link / histock
B14: 🔵 基本面 | C14: 每股盈餘(EPS) | D14: 歷史EPS、盈餘成長率、本益比高中低分位→目標價矩陣 | E14: 富邦證券
B15: 🔵 基本面 | C15: 股息&現金流 | D15: 歷年股利政策、殖利率、填息天數 | E15: Goodinfo等
B16: 🔵 基本面 | C16: 財報健檢 | D16: 資產負債表+現金流量表摘要與安全性指標(新增) | E16: 公開資訊觀測站
B17: 🟠 籌碼面 | C17: 籌碼 | D17: 法人買賣超、集中度、大戶比、融資券、券商分點 | E17: 富邦/histock
B18: 🟠 籌碼面 | C18: 期貨籌碼 | D18: 三大法人期貨未平倉(原「工作表54」) | E18: 期交所
B19: 🟢 市場面 | C19: 排行榜 | D19: 成交值排行、券資比排行(上市/上櫃) | E19: 富邦證券
... B22: ⚪ 參考 | C22: 減資一覽表 | D22: 減資股票調整用(現為手動填寫) | E22: money-link(停用)

Sheet 股價預估
A1: =證券編碼查詢!E2 -> 上市 | B1: 股票 | C1: =證券編碼查詢!D2 -> 台積電 | D1: 股本 | E1: 2330
A2: 市值 | D2: =股票資訊!B14 -> 2593.24
A3: =股票資訊!D6/100&"億" -> 621080.26億 | B3: 股價 | C3: =股票資訊!H2 -> 2395 | D3: =IF(ISBLANK(C3)," ",IF(I25<0,"衰退股",IF(I25<0.8,"估總報酬PE昂貴",IF(I25<1.2,"估總報酬PE合理",IF(I25>1.2,"估總報酬PE便宜","估總報酬PE昂貴"))))) -> 估總報酬PE便宜
D4: =IF(ISBLANK(C3)," ",IF(H38<0,"衰退股",IF(G38>1.33,"PEG估值昂貴",IF(G38>0.67,"PEG估值合理",IF(G38>0,"PEG估值便宜","衰退股"))))) -> PEG估值便宜
A5: =IF(ISBLANK(C3)," ",IF(E39<>"",IF(E39>D39,"研發費佔營收季增","研發費佔營收季減"),"")) -> 研發費佔營收季減 | B5: =IF(ISBLANK(C3)," ",IF(J45>G30,"估殖利率成長","估殖利率衰退")) -> 估殖利率衰退 | C5: =IF(ISBLANK(C3)," ",IF(營業費用!E26>營業費用!E27,"存貨週轉季增","存貨週轉季減")) -> 存貨週轉季減 | D5: =IF(ISBLANK(C3)," ",IF('毛利率&業外'!E4>'毛利率&業外'!E5,"毛利季增","毛利季減")) -> 毛利季增 | E5: =IF(ISBLANK(C3)," ",IF(F45>F35,"估本益比河流上升","估本益比河流下滑")) -> 估本益比河流上升 | F5: =IF(ISBLANK(C3)," ",營收!V3) -> 長短期營收擴大
A6: =IF(ISBLANK(C3)," ",IF(E39<>"",IF(E39>B39,"研發費佔營收年增","研發費佔營收年減"),"")) -> 研發費佔營收年減 | B6: =IF(ISBLANK(C3)," ",IF(F45>F35,"估盈餘成長","估盈餘衰退")) -> 估盈餘成長 | C6: =IF(ISBLANK(C3)," ",IF(營業費用!E26>營業費用!E29,"估存貨週轉年增","估存貨週轉年減")) -> 估存貨週轉年減 | D6: =IF(ISBLANK(C3)," ",IF('毛利率&業外'!E4>'毛利率&業外'!E7,"估毛利年增","估毛利年減")) -> 估毛利年增 | E6: =IF(ISBLANK(C3)," ",IF(營收!H3>0,"累積年增率>0","累積年增率<0")) -> 累積年增率>0 | F6: =IF(ISBLANK(C3)," ",營收!Q3) -> 長短期YOY擴大
A7: =籌碼!S52 -> 外資賣超1天 | B7: 營收預估
A8: =籌碼!S54 -> 投信賣超1天 | B8: 近1個月營收(積極) | D8: 預估單季營收(單月*3),(總月/4),(近3月)
A9: =IF(ISBLANK(C3)," ","券資比"&IF(籌碼!AG8>籌碼!AG9,"上升","下降")) -> 券資比下降 | B9: =IF(ISBLANK(營收!B3),IF(B8="近1個月營收(積極)",營收!B91,IF(B8="近12個月營收",SUM(營收!B91:B102),SUM(營收!B91:B93)))/1000,IF(B8="近1個月營收(積極)",營收!B3,IF(B8="近12個月營收",SUM(營收!B3:B14),SUM(營收!B3:B5)))/1000) -> 467580.54 | D9: =IF(B8="近1個月營收(積極)",B9*3,IF(B8="近12個月營收",ABS(B9/4),B9)) -> 1402741.6
A10: =籌碼!AG8 -> 0.0013
A11: =籌碼!S55 -> 融資增加1天 | B11: 毛利預估
A12: =籌碼!S56 -> 融券減少2天 | B12: 預計單季營收 | C12: 近1季毛利率 | D12: 預估毛利
A13: =IF(ISBLANK(C3)," ","融資使用率"&IF(籌碼!AA8>籌碼!AA9,"上升","下降")) -> 融資使用率下降 | B13: =D9 -> 1402741.6 | C13: =IF(C12="近1季毛利率",IF('毛利率&業外'!E4=0,'毛利率&業外'!E5,'毛利率&業外'!E4),IF('毛利率&業外'!E4=0,AVERAGEIF('毛利率&業外'!E5:E8,">0"),AVERAGEIF('毛利率&業外'!E4:E7,">0"))) -> 0.6772 | D13: =B13*C13 -> 949936.63
A14: =籌碼!AA8 -> 0.0043
A15: 投信持股比 | B15: 營業利益預估
A16: =籌碼!R8 -> 0.036636762 | B16: 預估毛利 | C16: 平均4季營業費 | D16: 預估營業利益
A17: =IF(ISBLANK(C1)," ",股票資訊!H29) -> 10檔ETF持股 | B17: =D13 -> 949936.63 | C17: =IF(C16="近1季營業費",營業費用!F7,營業費用!H7) -> 92236 | D17: =B17-C17 -> 857700.63
A18: 預估殖利率
A19: =J43/C3 -> 0.014245223 | B19: 業外收益預估
B20: 預估營業利益 | C20: 業外收支(季均) | D20: 預估稅前淨利 | F20: 預估稅後淨利(季均)
A21: Beta值 | B21: =D17 -> 857700.63 | C21: =IF(C20="業外收支(季均)", IFERROR(AVERAGE('毛利率&業外'!H4:H7),0),0) -> 44201.5 | D21: =B21+C21 -> 901902.13 | F21: =IF(F20="預估稅後淨利(季均)",D21*營業費用!H13,D21*營業費用!E13) -> 758821.16
A22: =股票資訊!H8 -> 1.1 | C22: =C21/D21 -> 0.049009198 | F22: =IF(F20="預估稅後淨利(季均)",營業費用!H13,營業費用!E13) -> 0.84135643
B23: EPS計算
A24: 標準差 | B24: 近季母公司稅後 | C24: 估母公司稅後 | D24: 近一季EPS | E24: 預估季EPS | F24: 估EPS季成長率 | G24: =H37 -> 預估盈餘成長率 | H24: 估年殖利率 | I24: 估總報酬PE
A25: =股票資訊!H9 -> 0.0208 | B25: =營業費用!F10 -> 706561.9 | C25: =F21-營業費用!H11 -> 758905.16 | D25: =E35 -> 27.25 | E25: =IF(ISBLANK(C3)," ",IF(E24="預估季EPS",C25*D25/B25,(C25*D25/B25)/(1-IF(C1="","",VLOOKUP(C1,減資一覽表!B:E,4,FALSE))))) -> 29.268725 | F25: =IF(D25<0,1-(E25/D25),(E25-D45)/D45) -> 0.074081634 | G25: =H38 -> 0.35691815 | H25: =IF(H37="預估盈餘成長率",IF(E45<0,0,E45*4*H29/C3),J45) -> 0.01699908 | I25: =IF(H37="預估盈餘成長率",IF(G47=0,0,(G25+H25)/G47*100),IF(G45=0,0,(G25+H25)/G45*100)) -> 1.8278214
A26: =W56 -> 平均殖利率 | B26: 非控制權益(季均) | C26: =營業費用!K11 -> -84 | H26: 停止融卷期間 | I26: =IF(ISBLANK(證券編碼查詢!C41),證券編碼查詢!B41,證券編碼查詢!C41) -> 115/09/10 ~ 115/09/15
A27: =V56 -> 0.011208102 | B27: ='股息&現金流'!A1 -> 年度 | C27: ='股息&現金流'!B1 -> 2022 | D27: ='股息&現金流'!C1 -> 2023 | E27: ='股息&現金流'!D1 -> 2024 | F27: ='股息&現金流'!E1 -> 2025 | G27: ='股息&現金流'!F1 -> 2026 | H27: =G27+1&"預估" -> 2027預估
A28: 平均配息率 | B28: ='股息&現金流'!A2 -> 現金股利 | C28: ='股息&現金流'!B2 -> 10.974 | D28: ='股息&現金流'!C2 -> 12.9987 | E28: ='股息&現金流'!D2 -> 17.04 | F28: ='股息&現金流'!E2 -> 22.099 | G28: ='股息&現金流'!F2 -> - | H28: =J43 -> 34.117309 | I28: 預估現金股利
A29: =IF(A28="平均配息率",IF(G29="無",AVERAGEIF(C29:F29,">=0")/100,AVERAGEIF(C29:G29,">=0")/100),IF(G29="無",F29/100,G29/100)) -> 0.34775 | B29: ='股息&現金流'!A3 -> 現金股利發放率 | C29: ='股息&現金流'!B3 -> 28.1 | D29: ='股息&現金流'!C3 -> 40.2 | E29: ='股息&現金流'!D3 -> 37.6 | F29: ='股息&現金流'!E3 -> 33.2 | G29: ='股息&現金流'!F3 -> - | H29: =A29 -> 0.34775 | I29: 預估發放率
C30: ='股息&現金流'!B4 -> 0.0186 | D30: ='股息&現金流'!C4 -> 0.0143 | E30: ='股息&現金流'!D4 -> 0.016 | F30: ='股息&現金流'!E4 -> 0.0098 | G30: ='股息&現金流'!F4 -> - | H30: =J45 -> 0.014245223 | I30: 預估殖利率
A31: =股票資訊!B21 -> 晶圓-5奈米30.98%、晶圓-3奈米20.85%、其他14.08%、晶圓-7奈米12.06%、晶圓-28奈米5.91%、晶圓-16奈米5.66%、晶圓-65奈米3.16%、晶圓-40及45奈米2.51%、晶圓-0.15及0.18微米2.32%、晶圓-0.11及0.13微米1.28%、晶圓-90奈米0.56%、晶圓-0.25微米以上0.51%、晶圓-20奈米0.11% (2025年)
J32: 股利
J33: =IF(F35<0,0,F35*A29) -> 30.00387
A34: 現有 | B34: ='每股盈餘(EPS)'!A6 -> 114.3Q | C34: ='每股盈餘(EPS)'!A5 -> 114.4Q | D34: ='每股盈餘(EPS)'!A4 -> 115.1Q | E34: ='每股盈餘(EPS)'!A3 -> 115.2Q | F34: EPS | G34: 目前本益比 | H34: 股價 | I34: 空間 | J34: 殖利率
B35: ='每股盈餘(EPS)'!H6 -> 17.44 | C35: ='每股盈餘(EPS)'!H5 -> 19.51 | D35: ='每股盈餘(EPS)'!H4 -> 22.08 | E35: ='每股盈餘(EPS)'!H3 -> 27.25 | F35: =IF(B35+C35+D35+E35=0,"",B35+C35+D35+E35) -> 86.28 | G35: =IF(F35<0,0,C3/F35) -> 27.758461 | H35: =C3 -> 2395 | I35: =(H35-C3)/C3 -> 0 | J35: =J33/C3 -> 0.012527712
A36: 業外占比 | B36: ='毛利率&業外'!L7 -> 0.04698412
A37: 稅率(%) | B37: =營業費用!B13 -> 0.85988199 | E37: =IF(D37="","",(D37/F45)-1) | G37: 估本益成長比(PEG) | H37: 預估盈餘成長率 | J37: =IF(H37="近1年盈餘成長率","預估盈餘成長率","近1年盈餘成長率") -> 近1年盈餘成長率
A38: 毛利率 | B38: ='毛利率&業外'!E7 -> 0.5945 | G38: =IF(H37="預估盈餘成長率",G47/H38/100,G45/H38/100) -> 0.57315633 | H38: =IF(D37>0,E37,IF(H37="近1年盈餘成長率",'每股盈餘(EPS)'!P3,IF(H37="近3年盈餘成長率",'每股盈餘(EPS)'!Q3,IF(H37="近4年盈餘成長率",'每股盈餘(EPS)'!R3,IF(F35<0,1-(E45*4/F35),(E45*4/F35)-1))))) -> 0.35691815 | J38: =IF(H37="近1年盈餘成長率",(E45*4-F35)/F35,'每股盈餘(EPS)'!P3) -> 0.60308373
A39: =營業費用!A17 -> 研發費用/營收 | B39: =營業費用!B17 -> 0.064391419 | C39: =營業費用!C17 -> 0.062000192 | D39: =營業費用!D17 -> 0.059744713 | E39: =營業費用!E17 -> 0.057578145
G40: ="營收發布剩"&股票資訊!L8&"天" -> 營收發布剩19天 | H40: ="財報發布剩"&股票資訊!L7&"天" -> 財報發布剩65天 | I40: 除息日 | J40: =證券編碼查詢!C37 -> 115/09/16
...

Sheet 股票資訊
A1: =IFERROR(__xludf.DUMMYFUNCTION("IMPORTHTML(SUBSTITUTE(""https://fubon-ebrokerdj.fbs.com.tw/z/zc/zca/zca_股票代碼.djhtm"", ""股票代碼"",'股價預估'!E1),""table"",0)"),"台積電 (2330) 基本資料 最近交易日:08/14 市值單位:百萬") -> 台積電 (2330) 基本資料 最近交易日:08/14 市值單位:百萬
A2: =IFERROR(__xludf.DUMMYFUNCTION("""COMPUTED_VALUE"""),"開盤價") -> 開盤價 | B2: =IFERROR(__xludf.DUMMYFUNCTION("""COMPUTED_VALUE"""),2435) -> 2435 | C2: =IFERROR(__xludf.DUMMYFUNCTION("""COMPUTED_VALUE"""),"最高價") -> 最高價 | D2: =IFERROR(__xludf.DUMMYFUNCTION("""COMPUTED_VALUE"""),2440) -> 2440 | E2: =IFERROR(__xludf.DUMMYFUNCTION("""COMPUTED_VALUE"""),"最低價") -> 最低價 | F2: =IFERROR(__xludf.DUMMYFUNCTION("""COMPUTED_VALUE"""),2395) -> 2395 | G2: =IFERROR(__xludf.DUMMYFUNCTION("""COMPUTED_VALUE"""),"收盤價") -> 收盤價 | H2: =IFERROR(__xludf.DUMMYFUNCTION("""COMPUTED_VALUE"""),2395) -> 2395 | J2: 財報發布 | K2: 日期 | L2: 剩餘天數
A3: =IFERROR(__xludf.DUMMYFUNCTION("""COMPUTED_VALUE"""),"漲跌") -> 漲跌 | B3: =IFERROR(__xludf.DUMMYFUNCTION("""COMPUTED_VALUE"""),-40) -> -40 | C3: =IFERROR(__xludf.DUMMYFUNCTION("""COMPUTED_VALUE"""),"一年內最高價") -> 一年內最高價 | D3: =IFERROR(__xludf.DUMMYFUNCTION("""COMPUTED_VALUE"""),2535) -> 2535 | E3: =IFERROR(__xludf.DUMMYFUNCTION("""COMPUTED_VALUE"""),"一年內最低價") -> 一年內最低價 | F3: =IFERROR(__xludf.DUMMYFUNCTION("""COMPUTED_VALUE"""),1135) -> 1135 | J3: 第1季 | K3: =DATE(YEAR(TODAY()),5,15) -> 46157 | L3: =IF(NETWORKDAYS.INTL(TODAY(),K3)<0,"",NETWORKDAYS.INTL(TODAY(),K3))
A4: =IFERROR(__xludf.DUMMYFUNCTION("""COMPUTED_VALUE"""),"本益比") -> 本益比 | B4: =IFERROR(__xludf.DUMMYFUNCTION("""COMPUTED_VALUE"""),27.76) -> 27.76 | C4: =IFERROR(__xludf.DUMMYFUNCTION("""COMPUTED_VALUE"""),"一年內最大量") -> 一年內最大量 | D4: =IFERROR(__xludf.DUMMYFUNCTION("""COMPUTED_VALUE"""),104784) -> 104784 | E4: =IFERROR(__xludf.DUMMYFUNCTION("""COMPUTED_VALUE"""),"一年內最低量") -> 一年內最低量 | F4: =IFERROR(__xludf.DUMMYFUNCTION("""COMPUTED_VALUE"""),13707) -> 13707 | G4: =IFERROR(__xludf.DUMMYFUNCTION("""COMPUTED_VALUE"""),"成交量") -> 成交量 | H4: =IFERROR(__xludf.DUMMYFUNCTION("""COMPUTED_VALUE"""),21163) -> 21163 | J4: 第2季 | K4: =DATE(YEAR(TODAY()),8,14) -> 46248 | L4: =IF(NETWORKDAYS.INTL(TODAY(),K4)<0,"",NETWORKDAYS.INTL(TODAY(),K4))
A5: =IFERROR(__xludf.DUMMYFUNCTION("""COMPUTED_VALUE"""),"同業平均本益比") -> 同業平均本益比 | B5: =IFERROR(__xludf.DUMMYFUNCTION("""COMPUTED_VALUE"""),44.7) -> 44.7 | C5: =IFERROR(__xludf.DUMMYFUNCTION("""COMPUTED_VALUE"""),"一年來最高本益比") -> 一年來最高本益比 | D5: =IFERROR(__xludf.DUMMYFUNCTION("""COMPUTED_VALUE"""),34.87) -> 34.87 | E5: =IFERROR(__xludf.DUMMYFUNCTION("""COMPUTED_VALUE"""),"一年來最低本益比") -> 一年來最低本益比 | F5: =IFERROR(__xludf.DUMMYFUNCTION("""COMPUTED_VALUE"""),20.16) -> 20.16 | G5: =IFERROR(__xludf.DUMMYFUNCTION("""COMPUTED_VALUE"""),"盤後量") -> 盤後量 | H5: =IFERROR(__xludf.DUMMYFUNCTION("""COMPUTED_VALUE"""),2238) -> 2238 | J5: 第3季 | K5: =DATE(YEAR(TODAY()),11,14) -> 46340 | L5: =IF(NETWORKDAYS.INTL(TODAY(),K5)<0,"",NETWORKDAYS.INTL(TODAY(),K5)) -> 65
A6: =IFERROR(__xludf.DUMMYFUNCTION("""COMPUTED_VALUE"""),"殖利率") -> 殖利率 | B6: =IFERROR(__xludf.DUMMYFUNCTION("""COMPUTED_VALUE"""),0.0092) -> 0.0092 | C6: =IFERROR(__xludf.DUMMYFUNCTION("""COMPUTED_VALUE"""),"總市值") -> 總市值 | D6: =IFERROR(__xludf.DUMMYFUNCTION("""COMPUTED_VALUE"""),62108026) -> 62108026 | E6: =IFERROR(__xludf.DUMMYFUNCTION("""COMPUTED_VALUE"""),"85年來最高總市值") -> 85年來最高總市值 | F6: =IFERROR(__xludf.DUMMYFUNCTION("""COMPUTED_VALUE"""),65090249) -> 65090249 | G6: =IFERROR(__xludf.DUMMYFUNCTION("""COMPUTED_VALUE"""),"85年來最低總市值") -> 85年來最低總市值 | H6: =IFERROR(__xludf.DUMMYFUNCTION("""COMPUTED_VALUE"""),92816) -> 92816 | J6: 第4季 | K6: =IF(MONTH(TODAY())=12,DATE(YEAR(TODAY())+1,3, 31),DATE(YEAR(TODAY()),3, 31)) -> 46112 | L6: =IF(NETWORKDAYS.INTL(TODAY(),K6)<0,"",NETWORKDAYS.INTL(TODAY(),K6))
A7: =IFERROR(__xludf.DUMMYFUNCTION("""COMPUTED_VALUE"""),"投資報酬率(08/14)") -> 投資報酬率(08/14) | C7: =IFERROR(__xludf.DUMMYFUNCTION("""COMPUTED_VALUE"""),"財務比例(115.2Q)") -> 財務比例(115.2Q) | E7: =IFERROR(__xludf.DUMMYFUNCTION("""COMPUTED_VALUE"""),"獲利能力(115.2Q)") -> 獲利能力(115.2Q) | G7: =IFERROR(__xludf.DUMMYFUNCTION("""COMPUTED_VALUE"""),"投資風險(08/14)") -> 投資風險(08/14) | L7: =MIN(L3:L6) -> 65
A8: =IFERROR(__xludf.DUMMYFUNCTION("""COMPUTED_VALUE"""),"今年以來") -> 今年以來 | B8: =IFERROR(__xludf.DUMMYFUNCTION("""COMPUTED_VALUE"""),0.5803) -> 0.5803 | C8: =IFERROR(__xludf.DUMMYFUNCTION("""COMPUTED_VALUE"""),"每股淨值(元)") -> 每股淨值(元) | D8: =ROUND(財報健檢!B36,2) -> 249.67 | E8: =IFERROR(__xludf.DUMMYFUNCTION("""COMPUTED_VALUE"""),"營業毛利率") -> 營業毛利率 | F8: =IFERROR(__xludf.DUMMYFUNCTION("""COMPUTED_VALUE"""),0.6772) -> 0.6772 | G8: =IFERROR(__xludf.DUMMYFUNCTION("""COMPUTED_VALUE"""),"貝他值") -> 貝他值 | H8: =IFERROR(__xludf.DUMMYFUNCTION("""COMPUTED_VALUE"""),1.1) -> 1.1 | J8: 營收發布 | K8: =IF(MONTH(TODAY())=12,IF(DAY(TODAY())>10,DATE(YEAR(TODAY())+1, 1, 10),DATE(YEAR(TODAY()), 12, 10)),IF(DAY(TODAY())<10, DATE(YEAR(TODAY()), MONTH(TODAY()), 10),DATE(YEAR(TODAY()), MONTH(TODAY())+1, 10))) -> 46275 | L8: =IF(MONTH(TODAY())=12,IF(DAY(TODAY())>10,NETWORKDAYS.INTL(TODAY(), DATE(YEAR(TODAY())+1, 1, 10)),NETWORKDAYS.INTL(TODAY(), DATE(YEAR(TODAY()), 12, 10))),IF(DAY(TODAY())<10,NETWORKDAYS.INTL(TODAY(), DATE(YEAR(TODAY()), MONTH(TODAY()), 10)),NETWORKDAYS.INTL(TODAY(), DATE(YEAR(TODAY()), MONTH(TODAY())+1, 10)))) -> 19
A9: =IFERROR(__xludf.DUMMYFUNCTION("""COMPUTED_VALUE"""),"最近一週") -> 最近一週 | B9: =IFERROR(__xludf.DUMMYFUNCTION("""COMPUTED_VALUE"""),0.0274) -> 0.0274 | C9: =IFERROR(__xludf.DUMMYFUNCTION("""COMPUTED_VALUE"""),"每人營收(仟元)") -> 每人營收(仟元) | D9: =IFERROR(__xludf.DUMMYFUNCTION("""COMPUTED_VALUE"""),13906) -> 13906 | E9: =IFERROR(__xludf.DUMMYFUNCTION("""COMPUTED_VALUE"""),"營業利益率") -> 營業利益率 | F9: =IFERROR(__xludf.DUMMYFUNCTION("""COMPUTED_VALUE"""),0.6034) -> 0.6034 | G9: =IFERROR(__xludf.DUMMYFUNCTION("""COMPUTED_VALUE"""),"標準差") -> 標準差 | H9: =IFERROR(__xludf.DUMMYFUNCTION("""COMPUTED_VALUE"""),0.0208) -> 0.0208
A10: =IFERROR(__xludf.DUMMYFUNCTION("""COMPUTED_VALUE"""),"最近一個月") -> 最近一個月 | B10: =IFERROR(__xludf.DUMMYFUNCTION("""COMPUTED_VALUE"""),0.0062) -> 0.0062 | C10: =IFERROR(__xludf.DUMMYFUNCTION("""COMPUTED_VALUE"""),"每股營收(元)") -> 每股營收(元) | D10: =IFERROR(__xludf.DUMMYFUNCTION("""COMPUTED_VALUE"""),48.99) -> 48.99 | E10: =IFERROR(__xludf.DUMMYFUNCTION("""COMPUTED_VALUE"""),"稅前淨利率") -> 稅前淨利率 | F10: =IFERROR(__xludf.DUMMYFUNCTION("""COMPUTED_VALUE"""),0.6789) -> 0.6789
A11: =IFERROR(__xludf.DUMMYFUNCTION("""COMPUTED_VALUE"""),"最近二個月") -> 最近二個月 | B11: =IFERROR(__xludf.DUMMYFUNCTION("""COMPUTED_VALUE"""),0.0541) -> 0.0541 | C11: =IFERROR(__xludf.DUMMYFUNCTION("""COMPUTED_VALUE"""),"負債比例") -> 負債比例 | D11: =IFERROR(__xludf.DUMMYFUNCTION("""COMPUTED_VALUE"""),0.3094) -> 0.3094 | E11: =IFERROR(__xludf.DUMMYFUNCTION("""COMPUTED_VALUE"""),"資產報酬率") -> 資產報酬率 | F11: =IFERROR(__xludf.DUMMYFUNCTION("""COMPUTED_VALUE"""),0.0786) -> 0.0786
A12: =IFERROR(__xludf.DUMMYFUNCTION("""COMPUTED_VALUE"""),"最近三個月") -> 最近三個月 | B12: =IFERROR(__xludf.DUMMYFUNCTION("""COMPUTED_VALUE"""),0.0755) -> 0.0755 | C12: =IFERROR(__xludf.DUMMYFUNCTION("""COMPUTED_VALUE"""),"股價淨值比") -> 股價淨值比 | D12: =ROUND(財報健檢!B37,2) -> 9.59 | E12: =IFERROR(__xludf.DUMMYFUNCTION("""COMPUTED_VALUE"""),"股東權益報酬率") -> 股東權益報酬率 | F12: =IFERROR(__xludf.DUMMYFUNCTION("""COMPUTED_VALUE"""),0.1139) -> 0.1139
A13: =IFERROR(__xludf.DUMMYFUNCTION("""COMPUTED_VALUE"""),"基本資料") -> 基本資料 | C13: =IFERROR(__xludf.DUMMYFUNCTION("""COMPUTED_VALUE"""),"配股配息(115[累計至 第二季])") -> 配股配息(115[累計至 第二季])
A14: =IFERROR(__xludf.DUMMYFUNCTION("""COMPUTED_VALUE"""),"股本(億, 台幣)") -> 股本(億, 台幣) | B14: =IFERROR(__xludf.DUMMYFUNCTION("""COMPUTED_VALUE"""),2593.24) -> 2593.24 | C14: =IFERROR(__xludf.DUMMYFUNCTION("""COMPUTED_VALUE"""),"現金股利(元)") -> 現金股利(元) | D14: =IFERROR(__xludf.DUMMYFUNCTION("""COMPUTED_VALUE"""),14) -> 14
A15: =IFERROR(__xludf.DUMMYFUNCTION("""COMPUTED_VALUE"""),"成立時間") -> 成立時間 | B15: =IFERROR(__xludf.DUMMYFUNCTION("""COMPUTED_VALUE"""),27811) -> 27811 | C15: =IFERROR(__xludf.DUMMYFUNCTION("""COMPUTED_VALUE"""),"股票股利") -> 股票股利 | D15: =IFERROR(__xludf.DUMMYFUNCTION("""COMPUTED_VALUE"""),0) -> 0
A16: =IFERROR(__xludf.DUMMYFUNCTION("""COMPUTED_VALUE"""),"初次上市(櫃)日期") -> 初次上市(櫃)日期 | B16: =IFERROR(__xludf.DUMMYFUNCTION("""COMPUTED_VALUE"""),30564) -> 30564 | C16: =IFERROR(__xludf.DUMMYFUNCTION("""COMPUTED_VALUE"""),"盈餘配股") -> 盈餘配股 | D16: =IFERROR(__xludf.DUMMYFUNCTION("""COMPUTED_VALUE"""),0) -> 0
A17: =IFERROR(__xludf.DUMMYFUNCTION("""COMPUTED_VALUE"""),"股務代理") -> 股務代理 | B17: =IFERROR(__xludf.DUMMYFUNCTION("""COMPUTED_VALUE"""),"中信託 02-66365566") -> 中信託 02-66365566 | C17: =IFERROR(__xludf.DUMMYFUNCTION("""COMPUTED_VALUE"""),"公積配股") -> 公積配股 | D17: =IFERROR(__xludf.DUMMYFUNCTION("""COMPUTED_VALUE"""),0) -> 0
A18: =IFERROR(__xludf.DUMMYFUNCTION("""COMPUTED_VALUE"""),"董事長") -> 董事長 | B18: =IFERROR(__xludf.DUMMYFUNCTION("""COMPUTED_VALUE"""),"魏哲家") -> 魏哲家
A19: =IFERROR(__xludf.DUMMYFUNCTION("""COMPUTED_VALUE"""),"總經理") -> 總經理 | B19: =IFERROR(__xludf.DUMMYFUNCTION("""COMPUTED_VALUE"""),"魏哲家") -> 魏哲家
A20: =IFERROR(__xludf.DUMMYFUNCTION("""COMPUTED_VALUE"""),"發言人") -> 發言人 | B20: =IFERROR(__xludf.DUMMYFUNCTION("""COMPUTED_VALUE"""),"黃仁昭") -> 黃仁昭
A21: =IFERROR(__xludf.DUMMYFUNCTION("""COMPUTED_VALUE"""),"營收比重") -> 營收比重 | B21: =IFERROR(__xludf.DUMMYFUNCTION("""COMPUTED_VALUE"""),"晶圓-5奈米30.98%、晶圓-3奈米20.85%、其他14.08%、晶圓-7奈米12.06%、晶圓-28奈米5.91%、晶圓-16奈米5.66%、晶圓-65奈米3.16%、晶圓-40及45奈米2.51%、晶圓-0.15及0.18微米2.32%、晶圓-0.11及0.13微米1.28%、晶圓-90奈米0.56%、晶圓-0.25微米以上0.51%、晶圓-20奈米0.11% (2025年)") -> 晶圓-5奈米30.98%、晶圓-3奈米20.85%、其他14.08%、晶圓-7奈米12.06%、晶圓-28奈米5.91%、晶圓-16奈米5.66%、晶圓-65奈米3.16%、晶圓-40及45奈米2.51%、晶圓-0.15及0.18微米2.32%、晶圓-0.11及0.13微米1.28%、晶圓-90奈米0.56%、晶圓-0.25微米以上0.51%、晶圓-20奈米0.11% (2025年)
A22: =IFERROR(__xludf.DUMMYFUNCTION("""COMPUTED_VALUE"""),"公司電話") -> 公司電話 | B22: =IFERROR(__xludf.DUMMYFUNCTION("""COMPUTED_VALUE"""),"03-5636688") -> 03-5636688
A23: =IFERROR(__xludf.DUMMYFUNCTION("""COMPUTED_VALUE"""),"網址") -> 網址 | B23: =IFERROR(__xludf.DUMMYFUNCTION("""COMPUTED_VALUE"""),"https://www.tsmc.com") -> https://www.tsmc.com
A24: =IFERROR(__xludf.DUMMYFUNCTION("""COMPUTED_VALUE"""),"公司地址") -> 公司地址 | B24: =IFERROR(__xludf.DUMMYFUNCTION("""COMPUTED_VALUE"""),"新竹科學園區力行六路8號") -> 新竹科學園區力行六路8號
A25: =IFERROR(__xludf.DUMMYFUNCTION("""COMPUTED_VALUE"""),"[TABLE]") -> [TABLE]
A26: =IFERROR(__xludf.DUMMYFUNCTION("""COMPUTED_VALUE"""),"說明") -> 說明 | B26: =IFERROR(__xludf.DUMMYFUNCTION("""COMPUTED_VALUE"""),"上方""年度""表格中的最高與最低數據是年度內統計(01/01-12/31)資料。 本益比數據由交易所提供。 [TABLE]") -> 上方"年度"表格中的最高與最低數據是年度內統計(01/01-12/31)資料。 本益比數據由交易所提供。 [TABLE]
A28: =IFERROR(__xludf.DUMMYFUNCTION("IMPORTHTML(SUBSTITUTE(""https://www.cmoney.tw/forum/stock/股票代碼?s=fund-holdings"", ""股票代碼"",'股價預估'!E1),""table"",0)"),"基金名稱") -> 基金名稱 | B28: =IFERROR(__xludf.DUMMYFUNCTION("""COMPUTED_VALUE"""),"持股張數") -> 持股張數 | C28: =IFERROR(__xludf.DUMMYFUNCTION("""COMPUTED_VALUE"""),"持股金額(仟萬)") -> 持股金額(仟萬) | D28: =IFERROR(__xludf.DUMMYFUNCTION("""COMPUTED_VALUE"""),"持股比例") -> 持股比例 | E28: =IFERROR(__xludf.DUMMYFUNCTION("""COMPUTED_VALUE"""),"月持股比例增減") -> 月持股比例增減
A29: =IFERROR(__xludf.DUMMYFUNCTION("""COMPUTED_VALUE"""),"ETF0052 富邦台灣科技指數基金") -> ETF0052 富邦台灣科技指數基金 | B29: =IFERROR(__xludf.DUMMYFUNCTION("""COMPUTED_VALUE"""),42376) -> 42376 | C29: =IFERROR(__xludf.DUMMYFUNCTION("""COMPUTED_VALUE"""),10212.62) -> 10212.62 | D29: =IFERROR(__xludf.DUMMYFUNCTION("""COMPUTED_VALUE"""),0.6341) -> 0.6341 | E29: =IFERROR(__xludf.DUMMYFUNCTION("""COMPUTED_VALUE"""),-0.0065) -> -0.0065 | H29: =COUNTA(A29:A75)&"檔ETF持股" -> 10檔ETF持股
A30: =IFERROR(__xludf.DUMMYFUNCTION("""COMPUTED_VALUE"""),"ETF006208 富邦台灣釆吉50基金") -> ETF006208 富邦台灣釆吉50基金 | B30: =IFERROR(__xludf.DUMMYFUNCTION("""COMPUTED_VALUE"""),108008) -> 108008 | C30: =IFERROR(__xludf.DUMMYFUNCTION("""COMPUTED_VALUE"""),26029.94) -> 26029.94 | D30: =IFERROR(__xludf.DUMMYFUNCTION("""COMPUTED_VALUE"""),0.5739) -> 0.5739 | E30: =IFERROR(__xludf.DUMMYFUNCTION("""COMPUTED_VALUE"""),-0.0091) -> -0.0091
A31: =IFERROR(__xludf.DUMMYFUNCTION("""COMPUTED_VALUE"""),"ETF0050 元大台灣卓越50基金") -> ETF0050 元大台灣卓越50基金 | B31: =IFERROR(__xludf.DUMMYFUNCTION("""COMPUTED_VALUE"""),525991) -> 525991 | C31: =IFERROR(__xludf.DUMMYFUNCTION("""COMPUTED_VALUE"""),126763.92) -> 126763.92 | D31: =IFERROR(__xludf.DUMMYFUNCTION("""COMPUTED_VALUE"""),0.5737) -> 0.5737 | E31: =IFERROR(__xludf.DUMMYFUNCTION("""COMPUTED_VALUE"""),-0.0091) -> -0.0091
A32: =IFERROR(__xludf.DUMMYFUNCTION("""COMPUTED_VALUE"""),"ETF00692 富邦臺灣公司治理100基金") -> ETF00692 富邦臺灣公司治理100基金 | B32: =IFERROR(__xludf.DUMMYFUNCTION("""COMPUTED_VALUE"""),13200) -> 13200 | C32: =IFERROR(__xludf.DUMMYFUNCTION("""COMPUTED_VALUE"""),3181.22) -> 3181.22 | D32: =IFERROR(__xludf.DUMMYFUNCTION("""COMPUTED_VALUE"""),0.5624) -> 0.5624 | E32: =IFERROR(__xludf.DUMMYFUNCTION("""COMPUTED_VALUE"""),"+0.08%") -> +0.08%
A33: =IFERROR(__xludf.DUMMYFUNCTION("""COMPUTED_VALUE"""),"ETF006203 元大摩臺基金") -> ETF006203 元大摩臺基金 | B33: =IFERROR(__xludf.DUMMYFUNCTION("""COMPUTED_VALUE"""),452) -> 452 | C33: =IFERROR(__xludf.DUMMYFUNCTION("""COMPUTED_VALUE"""),109.05) -> 109.05 | D33: =IFERROR(__xludf.DUMMYFUNCTION("""COMPUTED_VALUE"""),0.5489) -> 0.5489 | E33: =IFERROR(__xludf.DUMMYFUNCTION("""COMPUTED_VALUE"""),-0.001) -> -0.001
A34: =IFERROR(__xludf.DUMMYFUNCTION("""COMPUTED_VALUE"""),"ETF0057 富邦台灣ETF傘型基金之富邦台灣摩根指數股票型基金") -> ETF0057 富邦台灣ETF傘型基金之富邦台灣摩根指數股票型基金 | B34: =IFERROR(__xludf.DUMMYFUNCTION("""COMPUTED_VALUE"""),110) -> 110 | C34: =IFERROR(__xludf.DUMMYFUNCTION("""COMPUTED_VALUE"""),26.54) -> 26.54 | D34: =IFERROR(__xludf.DUMMYFUNCTION("""COMPUTED_VALUE"""),0.5485) -> 0.5485 | E34: =IFERROR(__xludf.DUMMYFUNCTION("""COMPUTED_VALUE"""),-0.0022) -> -0.0022
A35: =IFERROR(__xludf.DUMMYFUNCTION("""COMPUTED_VALUE"""),"ETF0053 元大台灣電子科技基金") -> ETF0053 元大台灣電子科技基金 | B35: =IFERROR(__xludf.DUMMYFUNCTION("""COMPUTED_VALUE"""),276) -> 276 | C35: =IFERROR(__xludf.DUMMYFUNCTION("""COMPUTED_VALUE"""),66.6) -> 66.6 | D35: =IFERROR(__xludf.DUMMYFUNCTION("""COMPUTED_VALUE"""),0.4974) -> 0.4974 | E35: =IFERROR(__xludf.DUMMYFUNCTION("""COMPUTED_VALUE"""),"+0.27%") -> +0.27%
A36: =IFERROR(__xludf.DUMMYFUNCTION("""COMPUTED_VALUE"""),"ETF009809 富邦台灣淨零轉型ESG50ETF基金") -> ETF009809 富邦台灣淨零轉型ESG50ETF基金 | B36: =IFERROR(__xludf.DUMMYFUNCTION("""COMPUTED_VALUE"""),97) -> 97 | C36: =IFERROR(__xludf.DUMMYFUNCTION("""COMPUTED_VALUE"""),23.52) -> 23.52 | D36: =IFERROR(__xludf.DUMMYFUNCTION("""COMPUTED_VALUE"""),0.4276) -> 0.4276 | E36: =IFERROR(__xludf.DUMMYFUNCTION("""COMPUTED_VALUE"""),"+14.21%") -> +14.21%
A37: =IFERROR(__xludf.DUMMYFUNCTION("""COMPUTED_VALUE"""),"ETF00904 台新臺灣全市場半導體精選30ETF基金") -> ETF00904 台新臺灣全市場半導體精選30ETF基金 | B37: =IFERROR(__xludf.DUMMYFUNCTION("""COMPUTED_VALUE"""),1266) -> 1266 | C37: =IFERROR(__xludf.DUMMYFUNCTION("""COMPUTED_VALUE"""),305.11) -> 305.11 | D37: =IFERROR(__xludf.DUMMYFUNCTION("""COMPUTED_VALUE"""),0.4156) -> 0.4156 | E37: =IFERROR(__xludf.DUMMYFUNCTION("""COMPUTED_VALUE"""),"+5.40%") -> +5.40%
A38: =IFERROR(__xludf.DUMMYFUNCTION("""COMPUTED_VALUE"""),"ETF009803 玉山臺灣市值動能50ETF基金") -> ETF009803 玉山臺灣市值動能50ETF基金 | B38: =IFERROR(__xludf.DUMMYFUNCTION("""COMPUTED_VALUE"""),618) -> 618 | C38: =IFERROR(__xludf.DUMMYFUNCTION("""COMPUTED_VALUE"""),148.94) -> 148.94 | D38: =IFERROR(__xludf.DUMMYFUNCTION("""COMPUTED_VALUE"""),0.4114) -> 0.4114 | E38: =IFERROR(__xludf.DUMMYFUNCTION("""COMPUTED_VALUE"""),"+3.45%") -> +3.45%

Sheet 營收
A1: =IFERROR(__xludf.DUMMYFUNCTION("IMPORTHTML(SUBSTITUTE(""https://histock.tw/stock/股票代碼/%E8%B2%A1%E5%8B%99%E5%A0%B1%E8%A1%A8"", ""股票代碼"",'股價預估'!E1),""table"",0)"),"年度/月份") -> 年度/月份 | B1: =IFERROR(__xludf.DUMMYFUNCTION("""COMPUTED_VALUE"""),"營業收入（單位：千元）") -> 營業收入（單位：千元） | F1: =IFERROR(__xludf.DUMMYFUNCTION("""COMPUTED_VALUE"""),"累計營業收入（單位：千元）") -> 累計營業收入（單位：千元） | I1: ="★ 單月YOY "&TEXT(E3,"+0.0%;-0.0%")&" 累積YOY "&TEXT(H3,"+0.0%;-0.0%")&" "&Q3&" "&V3 -> ★ 單月YOY +44.7% 累積YOY +37.0% 長短期YOY擴大 長短期營收擴大
B2: =IFERROR(__xludf.DUMMYFUNCTION("""COMPUTED_VALUE"""),"單月營收") -> 單月營收 | C2: =IFERROR(__xludf.DUMMYFUNCTION("""COMPUTED_VALUE"""),"去年同月營收") -> 去年同月營收 | D2: =IFERROR(__xludf.DUMMYFUNCTION("""COMPUTED_VALUE"""),"單月月增率") -> 單月月增率 | E2: =IFERROR(__xludf.DUMMYFUNCTION("""COMPUTED_VALUE"""),"單月年增率") -> 單月年增率 | F2: =IFERROR(__xludf.DUMMYFUNCTION("""COMPUTED_VALUE"""),"累計營收") -> 累計營收 | G2: =IFERROR(__xludf.DUMMYFUNCTION("""COMPUTED_VALUE"""),"去年累計營收") -> 去年累計營收 | H2: =IFERROR(__xludf.DUMMYFUNCTION("""COMPUTED_VALUE"""),"累積年增率") -> 累積年增率 | J2: 近3個月營收 | K2: 去年近3個月營收 | L2: 近3個月營收YOY | M2: 近12個月營收 | N2: 去年近12個月營收 | O2: 近12個月營收YOY | P2: 長短期營收YOY間距 | S2: 近3個月平均營收 | T2: 近12個月平均營收 | U2: 長短期營收間距
A3: =IFERROR(__xludf.DUMMYFUNCTION("""COMPUTED_VALUE"""),46204) -> 46204 | B3: =IFERROR(__xludf.DUMMYFUNCTION("""COMPUTED_VALUE"""),467580544) -> 467580544 | C3: =IFERROR(__xludf.DUMMYFUNCTION("""COMPUTED_VALUE"""),323165696) -> 323165696 | D3: =IFERROR(__xludf.DUMMYFUNCTION("""COMPUTED_VALUE"""),0.056) -> 0.056 | E3: =IFERROR(__xludf.DUMMYFUNCTION("""COMPUTED_VALUE"""),0.447) -> 0.447 | F3: =IFERROR(__xludf.DUMMYFUNCTION("""COMPUTED_VALUE"""),2872064256) -> 2872064256 | G3: =IFERROR(__xludf.DUMMYFUNCTION("""COMPUTED_VALUE"""),2096211200) -> 2096211200 | H3: =IFERROR(__xludf.DUMMYFUNCTION("""COMPUTED_VALUE"""),0.37) -> 0.37 | I3: =A3 -> 46204 | J3: =IF(ISBLANK(B3),SUM(B91:B93),SUM(B3:B5)) -> 1327235680 | K3: =IF(ISBLANK(B3),SUM(B103:B105),SUM(B15:B17)) -> 907390592 | L3: =(J3-K3)/K3 -> 0.462695 | M3: =IF(ISBLANK(B3),SUM(B91:B102),SUM(B3:B14)) -> 4584907264 | N3: =IF(ISBLANK(B3),SUM(B103:B114),SUM(B15:B26)) -> 3467411424 | O3: =(M3-N3)/N3 -> 0.32228533 | P3: =L3-O3 -> 0.14040967 | Q3: =IF(P3>P4,"長短期YOY擴大","長短期YOY收斂") -> 長短期YOY擴大 | S3: =IF(ISBLANK(B3),AVERAGE(B91:B93),AVERAGE(B3:B5)) -> 4.4241189e+08 | T3: =IF(ISBLANK(B3),AVERAGE(B91:B102),AVERAGE(B3:B14)) -> 3.8207561e+08 | U3: =S3-T3 -> 60336288 | V3: =IF(U3>U4,"長短期營收擴大","長短期營收收斂") -> 長短期營收擴大 | AA3: =B3 -> 467580544 | AB3: =B15 -> 323165696 | AC3: =B27 -> 256953104
A4: =IFERROR(__xludf.DUMMYFUNCTION("""COMPUTED_VALUE"""),46174) -> 46174 | B4: =IFERROR(__xludf.DUMMYFUNCTION("""COMPUTED_VALUE"""),442679968) -> 442679968 | C4: =IFERROR(__xludf.DUMMYFUNCTION("""COMPUTED_VALUE"""),263708976) -> 263708976 | D4: =IFERROR(__xludf.DUMMYFUNCTION("""COMPUTED_VALUE"""),0.062) -> 0.062 | E4: =IFERROR(__xludf.DUMMYFUNCTION("""COMPUTED_VALUE"""),0.679) -> 0.679 | F4: =IFERROR(__xludf.DUMMYFUNCTION("""COMPUTED_VALUE"""),2404483584) -> 2404483584 | G4: =IFERROR(__xludf.DUMMYFUNCTION("""COMPUTED_VALUE"""),1773045504) -> 1773045504 | H4: =IFERROR(__xludf.DUMMYFUNCTION("""COMPUTED_VALUE"""),0.356) -> 0.356 | I4: =A4 -> 46174 | J4: =IF(ISBLANK(B4),SUM(B92:B94),SUM(B4:B6)) -> 1270380224 | K4: =IF(ISBLANK(B4),SUM(B104:B106),SUM(B16:B18)) -> 933791808 | L4: =(J4-K4)/K4 -> 0.36045338 | M4: =IF(ISBLANK(B4),SUM(B92:B103),SUM(B4:B15)) -> 4440492416 | N4: =IF(ISBLANK(B4),SUM(B104:B115),SUM(B16:B27)) -> 3401198832 | O4: =(M4-N4)/N4 -> 0.30556684 | P4: =L4-O4 -> 0.054886541 | Q4: =IF(P4>P5,"長短期YOY擴大","長短期YOY收斂") -> 長短期YOY擴大 | S4: =IF(ISBLANK(B4),AVERAGE(B92:B94),AVERAGE(B4:B6)) -> 4.2346007e+08 | T4: =IF(ISBLANK(B4),AVERAGE(B92:B103),AVERAGE(B4:B15)) -> 3.7004103e+08 | U4: =S4-T4 -> 53419040 | V4: =IF(U4>U5,"長短期營收擴大","長短期營收收斂") -> 長短期營收收斂 | AA4: =B4 -> 442679968 | AB4: =B16 -> 263708992 | AC4: =B28 -> 207868704
A5: =IFERROR(__xludf.DUMMYFUNCTION("""COMPUTED_VALUE"""),46143) -> 46143 | B5: =IFERROR(__xludf.DUMMYFUNCTION("""COMPUTED_VALUE"""),416975168) -> 416975168 | C5: =IFERROR(__xludf.DUMMYFUNCTION("""COMPUTED_VALUE"""),320515936) -> 320515936 | D5: =IFERROR(__xludf.DUMMYFUNCTION("""COMPUTED_VALUE"""),0.015) -> 0.015 | E5: =IFERROR(__xludf.DUMMYFUNCTION("""COMPUTED_VALUE"""),0.301) -> 0.301 | F5: =IFERROR(__xludf.DUMMYFUNCTION("""COMPUTED_VALUE"""),1961803776) -> 1961803776 | G5: =IFERROR(__xludf.DUMMYFUNCTION("""COMPUTED_VALUE"""),1509336576) -> 1509336576 | H5: =IFERROR(__xludf.DUMMYFUNCTION("""COMPUTED_VALUE"""),0.3) -> 0.3 | I5: =A5 -> 46143 | J5: =IF(ISBLANK(B5),SUM(B93:B95),SUM(B5:B7)) -> 1242891968 | K5: =IF(ISBLANK(B5),SUM(B105:B107),SUM(B17:B19)) -> 956039616 | L5: =(J5-K5)/K5 -> 0.30004233 | M5: =IF(ISBLANK(B5),SUM(B93:B104),SUM(B5:B16)) -> 4261521440 | N5: =IF(ISBLANK(B5),SUM(B105:B116),SUM(B17:B28)) -> 3345358544 | O5: =(M5-N5)/N5 -> 0.2738609 | P5: =L5-O5 -> 0.02618143 | Q5: =IF(P5>P6,"長短期YOY擴大","長短期YOY收斂") -> 長短期YOY擴大 | S5: =IF(ISBLANK(B5),AVERAGE(B93:B95),AVERAGE(B5:B7)) -> 4.1429732e+08 | T5: =IF(ISBLANK(B5),AVERAGE(B93:B104),AVERAGE(B5:B16)) -> 3.5512679e+08 | U5: =S5-T5 -> 59170536 | V5: =IF(U5>U6,"長短期營收擴大","長短期營收收斂") -> 長短期營收擴大 | AA5: =B5 -> 416975168 | AB5: =B17 -> 320515904 | AC5: =B29 -> 229620400
A6: =IFERROR(__xludf.DUMMYFUNCTION("""COMPUTED_VALUE"""),46113) -> 46113 | B6: =IFERROR(__xludf.DUMMYFUNCTION("""COMPUTED_VALUE"""),410725088) -> 410725088 | C6: =IFERROR(__xludf.DUMMYFUNCTION("""COMPUTED_VALUE"""),349566912) -> 349566912 | D6: =IFERROR(__xludf.DUMMYFUNCTION("""COMPUTED_VALUE"""),-0.011) -> -0.011 | E6: =IFERROR(__xludf.DUMMYFUNCTION("""COMPUTED_VALUE"""),0.175) -> 0.175 | F6: =IFERROR(__xludf.DUMMYFUNCTION("""COMPUTED_VALUE"""),1544829056) -> 1544829056 | G6: =IFERROR(__xludf.DUMMYFUNCTION("""COMPUTED_VALUE"""),1188820992) -> 1188820992 | H6: =IFERROR(__xludf.DUMMYFUNCTION("""COMPUTED_VALUE"""),0.299) -> 0.299 | I6: =A6 -> 46113 | J6: =IF(ISBLANK(B6),SUM(B94:B96),SUM(B6:B8)) -> 1143573408 | K6: =IF(ISBLANK(B6),SUM(B106:B108),SUM(B18:B20)) -> 895532512 | L6: =(J6-K6)/K6 -> 0.27697587 | M6: =IF(ISBLANK(B6),SUM(B94:B105),SUM(B6:B17)) -> 4165062176 | N6: =IF(ISBLANK(B6),SUM(B106:B117),SUM(B18:B29)) -> 3254463040 | O6: =(M6-N6)/N6 -> 0.27980012 | P6: =L6-O6 -> -0.0028242467 | Q6: =IF(P6>P7,"長短期YOY擴大","長短期YOY收斂") -> 長短期YOY收斂 | S6: =IF(ISBLANK(B6),AVERAGE(B94:B96),AVERAGE(B6:B8)) -> 381191136 | T6: =IF(ISBLANK(B6),AVERAGE(B94:B105),AVERAGE(B6:B17)) -> 3.4708851e+08 | U6: =S6-T6 -> 34102621 | V6: =IF(U6>U7,"長短期營收擴大","長短期營收收斂") -> 長短期營收收斂 | AA6: =B6 -> 410725088 | AB6: =B18 -> 349566912 | AC6: =B30 -> 236021104
A7: =IFERROR(__xludf.DUMMYFUNCTION("""COMPUTED_VALUE"""),46082) -> 46082 | B7: =IFERROR(__xludf.DUMMYFUNCTION("""COMPUTED_VALUE"""),415191712) -> 415191712 | C7: =IFERROR(__xludf.DUMMYFUNCTION("""COMPUTED_VALUE"""),285956800) -> 285956800 | D7: =IFERROR(__xludf.DUMMYFUNCTION("""COMPUTED_VALUE"""),0.307) -> 0.307 | E7: =IFERROR(__xludf.DUMMYFUNCTION("""COMPUTED_VALUE"""),0.452) -> 0.452 | F7: =IFERROR(__xludf.DUMMYFUNCTION("""COMPUTED_VALUE"""),1134103040) -> 1134103040 | G7: =IFERROR(__xludf.DUMMYFUNCTION("""COMPUTED_VALUE"""),839253632) -> 839253632 | H7: =IFERROR(__xludf.DUMMYFUNCTION("""COMPUTED_VALUE"""),0.351) -> 0.351 | I7: =A7 -> 46082 | J7: =IF(ISBLANK(B7),SUM(B95:B97),SUM(B7:B9)) -> 1134103424 | K7: =IF(ISBLANK(B7),SUM(B107:B109),SUM(B19:B21)) -> 839253600 | L7: =(J7-K7)/K7 -> 0.35132387 | M7: =IF(ISBLANK(B7),SUM(B95:B106),SUM(B7:B18)) -> 4103904000 | N7: =IF(ISBLANK(B7),SUM(B107:B118),SUM(B19:B30)) -> 3140917232 | O7: =(M7-N7)/N7 -> 0.30659412 | P7: =L7-O7 -> 0.044729747 | Q7: =IF(P7>P8,"長短期YOY擴大","長短期YOY收斂") -> 長短期YOY擴大 | S7: =IF(ISBLANK(B7),AVERAGE(B95:B97),AVERAGE(B7:B9)) -> 3.7803447e+08 | T7: =IF(ISBLANK(B7),AVERAGE(B95:B106),AVERAGE(B7:B18)) -> 341992000 | U7: =S7-T7 -> 36042475 | V7: =IF(U7>U8,"長短期營收擴大","長短期營收收斂") -> 長短期營收擴大 | AA7: =B7 -> 415191712 | AB7: =B19 -> 285956800 | AC7: =B31 -> 195210800
A8: =IFERROR(__xludf.DUMMYFUNCTION("""COMPUTED_VALUE"""),46054) -> 46054 | B8: =IFERROR(__xludf.DUMMYFUNCTION("""COMPUTED_VALUE"""),317656608) -> 317656608 | C8: =IFERROR(__xludf.DUMMYFUNCTION("""COMPUTED_VALUE"""),260008800) -> 260008800 | D8: =IFERROR(__xludf.DUMMYFUNCTION("""COMPUTED_VALUE"""),-0.208) -> -0.208 | E8: =IFERROR(__xludf.DUMMYFUNCTION("""COMPUTED_VALUE"""),0.222) -> 0.222 | F8: =IFERROR(__xludf.DUMMYFUNCTION("""COMPUTED_VALUE"""),718911680) -> 718911680 | G8: =IFERROR(__xludf.DUMMYFUNCTION("""COMPUTED_VALUE"""),553296768) -> 553296768 | H8: =IFERROR(__xludf.DUMMYFUNCTION("""COMPUTED_VALUE"""),0.299) -> 0.299 | I8: =A8 -> 46054 | J8: =IF(ISBLANK(B8),SUM(B96:B98),SUM(B8:B10)) -> 1053915296 | K8: =IF(ISBLANK(B8),SUM(B108:B110),SUM(B20:B22)) -> 831459904 | L8: =(J8-K8)/K8 -> 0.26754795 | M8: =IF(ISBLANK(B8),SUM(B96:B107),SUM(B8:B19)) -> 3974669088 | N8: =IF(ISBLANK(B8),SUM(B108:B119),SUM(B20:B31)) -> 3050171232 | O8: =(M8-N8)/N8 -> 0.30309703 | P8: =L8-O8 -> -0.035549086 | Q8: =IF(P8>P9,"長短期YOY擴大","長短期YOY收斂") -> 長短期YOY擴大 | S8: =IF(ISBLANK(B8),AVERAGE(B96:B98),AVERAGE(B8:B10)) -> 3.513051e+08 | T8: =IF(ISBLANK(B8),AVERAGE(B96:B107),AVERAGE(B8:B19)) -> 331222424 | U8: =S8-T8 -> 20082675 | V8: =IF(U8>U9,"長短期營收擴大","長短期營收收斂") -> 長短期營收收斂 | AA8: =B8 -> 317656608 | AB8: =B20 -> 260008800 | AC8: =B32 -> 181648304
A9: =IFERROR(__xludf.DUMMYFUNCTION("""COMPUTED_VALUE"""),46023) -> 46023 | B9: =IFERROR(__xludf.DUMMYFUNCTION("""COMPUTED_VALUE"""),401255104) -> 401255104 | C9: =IFERROR(__xludf.DUMMYFUNCTION("""COMPUTED_VALUE"""),293288000) -> 293288000 | D9: =IFERROR(__xludf.DUMMYFUNCTION("""COMPUTED_VALUE"""),0.198) -> 0.198 | E9: =IFERROR(__xludf.DUMMYFUNCTION("""COMPUTED_VALUE"""),0.368) -> 0.368 | F9: =IFERROR(__xludf.DUMMYFUNCTION("""COMPUTED_VALUE"""),401255104) -> 401255104 | G9: =IFERROR(__xludf.DUMMYFUNCTION("""COMPUTED_VALUE"""),293288000) -> 293288000 | H9: =IFERROR(__xludf.DUMMYFUNCTION("""COMPUTED_VALUE"""),0.368) -> 0.368 | I9: =A9 -> 46023 | J9: =IF(ISBLANK(B9),SUM(B97:B99),SUM(B9:B11)) -> 1079872480 | K9: =IF(ISBLANK(B9),SUM(B109:B111),SUM(B21:B23)) -> 847509504 | L9: =(J9-K9)/K9 -> 0.27417153 | M9: =IF(ISBLANK(B9),SUM(B97:B108),SUM(B9:B20)) -> 3917021280 | N9: =IF(ISBLANK(B9),SUM(B109:B120),SUM(B21:B32)) -> 2971810736 | O9: =(M9-N9)/N9 -> 0.3180588 | P9: =L9-O9 -> -0.043887267 | Q9: =IF(P9>P10,"長短期YOY擴大","長短期YOY收斂") -> 長短期YOY擴大 | S9: =IF(ISBLANK(B9),AVERAGE(B97:B99),AVERAGE(B9:B11)) -> 3.5995749e+08 | T9: =IF(ISBLANK(B9),AVERAGE(B97:B108),AVERAGE(B9:B20)) -> 326418440 | U9: =S9-T9 -> 33539053 | V9: =IF(U9>U10,"長短期營收擴大","長短期營收收斂") -> 長短期營收擴大 | AA9: =B9 -> 401255104 | AB9: =B21 -> 293288000 | AC9: =B33 -> 215785104
A10: =IFERROR(__xludf.DUMMYFUNCTION("""COMPUTED_VALUE"""),45992) -> 45992 | B10: =IFERROR(__xludf.DUMMYFUNCTION("""COMPUTED_VALUE"""),335003584) -> 335003584 | C10: =IFERROR(__xludf.DUMMYFUNCTION("""COMPUTED_VALUE"""),278163104) -> 278163104 | D10: =IFERROR(__xludf.DUMMYFUNCTION("""COMPUTED_VALUE"""),-0.025) -> -0.025 | E10: =IFERROR(__xludf.DUMMYFUNCTION("""COMPUTED_VALUE"""),0.204) -> 0.204 | F10: =IFERROR(__xludf.DUMMYFUNCTION("""COMPUTED_VALUE"""),3809053952) -> 3809053952 | G10: =IFERROR(__xludf.DUMMYFUNCTION("""COMPUTED_VALUE"""),2894308096) -> 2894308096 | H10: =IFERROR(__xludf.DUMMYFUNCTION("""COMPUTED_VALUE"""),0.316) -> 0.316 | I10: =A10 -> 45992 | J10: =IF(ISBLANK(B10),SUM(B98:B100),SUM(B10:B12)) -> 1046090464 | K10: =IF(ISBLANK(B10),SUM(B110:B112),SUM(B22:B24)) -> 868461216 | L10: =(J10-K10)/K10 -> 0.20453331 | M10: =IF(ISBLANK(B10),SUM(B98:B109),SUM(B10:B21)) -> 3809054176 | N10: =IF(ISBLANK(B10),SUM(B110:B121),SUM(B22:B33)) -> 2894307840 | O10: =(M10-N10)/N10 -> 0.31605012 | P10: =L10-O10 -> -0.11151681 | Q10: =IF(P10>P11,"長短期YOY擴大","長短期YOY收斂") -> 長短期YOY收斂 | S10: =IF(ISBLANK(B10),AVERAGE(B98:B100),AVERAGE(B10:B12)) -> 3.4869682e+08 | T10: =IF(ISBLANK(B10),AVERAGE(B98:B109),AVERAGE(B10:B21)) -> 3.1742118e+08 | U10: =S10-T10 -> 31275640 | V10: =IF(U10>U11,"長短期營收擴大","長短期營收收斂") -> 長短期營收收斂 | AA10: =B10 -> 335003584 | AB10: =B22 -> 278163104 | AC10: =B34 -> 176299904
A11: =IFERROR(__xludf.DUMMYFUNCTION("""COMPUTED_VALUE"""),45962) -> 45962 | B11: =IFERROR(__xludf.DUMMYFUNCTION("""COMPUTED_VALUE"""),343613792) -> 343613792 | C11: =IFERROR(__xludf.DUMMYFUNCTION("""COMPUTED_VALUE"""),276058400) -> 276058400 | D11: =IFERROR(__xludf.DUMMYFUNCTION("""COMPUTED_VALUE"""),-0.065) -> -0.065 | E11: =IFERROR(__xludf.DUMMYFUNCTION("""COMPUTED_VALUE"""),0.245) -> 0.245 | F11: =IFERROR(__xludf.DUMMYFUNCTION("""COMPUTED_VALUE"""),3474051072) -> 3474051072 | G11: =IFERROR(__xludf.DUMMYFUNCTION("""COMPUTED_VALUE"""),2616144896) -> 2616144896 | H11: =IFERROR(__xludf.DUMMYFUNCTION("""COMPUTED_VALUE"""),0.328) -> 0.328 | I11: =A11 -> 45962 | J11: =IF(ISBLANK(B11),SUM(B99:B101),SUM(B11:B13)) -> 1042067776 | K11: =IF(ISBLANK(B11),SUM(B111:B113),SUM(B23:B25)) -> 842170816 | L11: =(J11-K11)/K11 -> 0.23735916 | M11: =IF(ISBLANK(B11),SUM(B99:B110),SUM(B11:B22)) -> 3752213696 | N11: =IF(ISBLANK(B11),SUM(B111:B122),SUM(B23:B34)) -> 2792444640 | O11: =(M11-N11)/N11 -> 0.34370209 | P11: =L11-O11 -> -0.10634293 | Q11: =IF(P11>P12,"長短期YOY擴大","長短期YOY收斂") -> 長短期YOY收斂 | S11: =IF(ISBLANK(B11),AVERAGE(B99:B101),AVERAGE(B11:B13)) -> 3.4735593e+08 | T11: =IF(ISBLANK(B11),AVERAGE(B99:B110),AVERAGE(B11:B22)) -> 3.1268447e+08 | U11: =S11-T11 -> 34671451 | V11: =IF(U11>U12,"長短期營收擴大","長短期營收收斂") -> 長短期營收收斂 | AA11: =B11 -> 343613792 | AB11: =B23 -> 276058400 | AC11: =B35 -> 206026208
A12: =IFERROR(__xludf.DUMMYFUNCTION("""COMPUTED_VALUE"""),45931) -> 45931 | B12: =IFERROR(__xludf.DUMMYFUNCTION("""COMPUTED_VALUE"""),367473088) -> 367473088 | C12: =IFERROR(__xludf.DUMMYFUNCTION("""COMPUTED_VALUE"""),314239712) -> 314239712 | D12: =IFERROR(__xludf.DUMMYFUNCTION("""COMPUTED_VALUE"""),0.11) -> 0.11 | E12: =IFERROR(__xludf.DUMMYFUNCTION("""COMPUTED_VALUE"""),0.169) -> 0.169 | F12: =IFERROR(__xludf.DUMMYFUNCTION("""COMPUTED_VALUE"""),3130437120) -> 3130437120 | G12: =IFERROR(__xludf.DUMMYFUNCTION("""COMPUTED_VALUE"""),2340086016) -> 2340086016 | H12: =IFERROR(__xludf.DUMMYFUNCTION("""COMPUTED_VALUE"""),0.338) -> 0.338 | I12: =A12 -> 45931 | J12: =IF(ISBLANK(B12),SUM(B100:B102),SUM(B12:B14)) -> 1034225696 | K12: =IF(ISBLANK(B12),SUM(B112:B114),SUM(B24:B26)) -> 816978816 | L12: =(J12-K12)/K12 -> 0.26591495 | M12: =IF(ISBLANK(B12),SUM(B100:B111),SUM(B12:B23)) -> 3684658304 | N12: =IF(ISBLANK(B12),SUM(B112:B123),SUM(B24:B35)) -> 2722412448 | O12: =(M12-N12)/N12 -> 0.35345337 | P12: =L12-O12 -> -0.087538422 | Q12: =IF(P12>P13,"長短期YOY擴大","長短期YOY收斂") -> 長短期YOY收斂 | S12: =IF(ISBLANK(B12),AVERAGE(B100:B102),AVERAGE(B12:B14)) -> 3.447419e+08 | T12: =IF(ISBLANK(B12),AVERAGE(B100:B111),AVERAGE(B12:B23)) -> 3.0705486e+08 | U12: =S12-T12 -> 37687040 | V12: =IF(U12>U13,"長短期營收擴大","長短期營收收斂") -> 長短期營收擴大 | AA12: =B12 -> 367473088 | AB12: =B24 -> 314239712 | AC12: =B36 -> 243202800
A13: =IFERROR(__xludf.DUMMYFUNCTION("""COMPUTED_VALUE"""),45901) -> 45901 | B13: =IFERROR(__xludf.DUMMYFUNCTION("""COMPUTED_VALUE"""),330980896) -> 330980896 | C13: =IFERROR(__xludf.DUMMYFUNCTION("""COMPUTED_VALUE"""),251872704) -> 251872704 | D13: =IFERROR(__xludf.DUMMYFUNCTION("""COMPUTED_VALUE"""),-0.014) -> -0.014 | E13: =IFERROR(__xludf.DUMMYFUNCTION("""COMPUTED_VALUE"""),0.314) -> 0.314 | F13: =IFERROR(__xludf.DUMMYFUNCTION("""COMPUTED_VALUE"""),2762963968) -> 2762963968 | G13: =IFERROR(__xludf.DUMMYFUNCTION("""COMPUTED_VALUE"""),2025847040) -> 2025847040 | H13: =IFERROR(__xludf.DUMMYFUNCTION("""COMPUTED_VALUE"""),0.364) -> 0.364 | I13: =A13 -> 45901 | J13: =IF(ISBLANK(B13),SUM(B101:B103),SUM(B13:B15)) -> 989918304 | K13: =IF(ISBLANK(B13),SUM(B113:B115),SUM(B25:B27)) -> 759692208 | L13: =(J13-K13)/K13 -> 0.30305181 | M13: =IF(ISBLANK(B13),SUM(B101:B112),SUM(B13:B24)) -> 3631424928 | N13: =IF(ISBLANK(B13),SUM(B113:B124),SUM(B25:B36)) -> 2651375536 | O13: =(M13-N13)/N13 -> 0.36963809 | P13: =L13-O13 -> -0.066586285 | Q13: =IF(P13>P14,"長短期YOY擴大","長短期YOY收斂") -> 長短期YOY擴大 | S13: =IF(ISBLANK(B13),AVERAGE(B101:B103),AVERAGE(B13:B15)) -> 329972768 | T13: =IF(ISBLANK(B13),AVERAGE(B101:B112),AVERAGE(B13:B24)) -> 302618744 | U13: =S13-T13 -> 27354024 | V13: =IF(U13>U14,"長短期營收擴大","長短期營收收斂") -> 長短期營收擴大 | AA13: =B13 -> 330980896 | AB13: =B25 -> 251872704 | AC13: =B37 -> 180430304
A14: =IFERROR(__xludf.DUMMYFUNCTION("""COMPUTED_VALUE"""),45870) -> 45870 | B14: =IFERROR(__xludf.DUMMYFUNCTION("""COMPUTED_VALUE"""),335771712) -> 335771712 | C14: =IFERROR(__xludf.DUMMYFUNCTION("""COMPUTED_VALUE"""),250866400) -> 250866400 | D14: =IFERROR(__xludf.DUMMYFUNCTION("""COMPUTED_VALUE"""),0.039) -> 0.039 | E14: =IFERROR(__xludf.DUMMYFUNCTION("""COMPUTED_VALUE"""),0.338) -> 0.338 | F14: =IFERROR(__xludf.DUMMYFUNCTION("""COMPUTED_VALUE"""),2431983104) -> 2431983104 | G14: =IFERROR(__xludf.DUMMYFUNCTION("""COMPUTED_VALUE"""),1773974016) -> 1773974016 | H14: =IFERROR(__xludf.DUMMYFUNCTION("""COMPUTED_VALUE"""),0.371) -> 0.371 | I14: =A14 -> 45870 | J14: =IF(ISBLANK(B14),SUM(B102:B104),SUM(B14:B16)) -> 922646400 | K14: =IF(ISBLANK(B14),SUM(B114:B116),SUM(B26:B28)) -> 715688208 | L14: =(J14-K14)/K14 -> 0.28917368 | M14: =IF(ISBLANK(B14),SUM(B102:B113),SUM(B14:B25)) -> 3552316736 | N14: =IF(ISBLANK(B14),SUM(B114:B125),SUM(B26:B37)) -> 2579933136 | O14: =(M14-N14)/N14 -> 0.37690264 | P14: =L14-O14 -> -0.087728957 | Q14: =IF(P14>P15,"長短期YOY擴大","長短期YOY收斂") -> 長短期YOY收斂 | S14: =IF(ISBLANK(B14),AVERAGE(B102:B104),AVERAGE(B14:B16)) -> 307548800 | T14: =IF(ISBLANK(B14),AVERAGE(B102:B113),AVERAGE(B14:B25)) -> 2.9602639e+08 | U14: =S14-T14 -> 11522405 | V14: =IF(U14>U15,"長短期營收擴大","長短期營收收斂") -> 長短期營收收斂 | AA14: =B14 -> 335771712 | AB14: =B26 -> 250866400 | AC14: =B38 -> 188686304
A15: =IFERROR(__xludf.DUMMYFUNCTION("""COMPUTED_VALUE"""),45839) -> 45839 | B15: =IFERROR(__xludf.DUMMYFUNCTION("""COMPUTED_VALUE"""),323165696) -> 323165696 | C15: =IFERROR(__xludf.DUMMYFUNCTION("""COMPUTED_VALUE"""),256953104) -> 256953104 | D15: =IFERROR(__xludf.DUMMYFUNCTION("""COMPUTED_VALUE"""),0.225) -> 0.225 | E15: =IFERROR(__xludf.DUMMYFUNCTION("""COMPUTED_VALUE"""),0.258) -> 0.258 | F15: =IFERROR(__xludf.DUMMYFUNCTION("""COMPUTED_VALUE"""),2096210944) -> 2096210944 | G15: =IFERROR(__xludf.DUMMYFUNCTION("""COMPUTED_VALUE"""),1523106944) -> 1523106944 | H15: =IFERROR(__xludf.DUMMYFUNCTION("""COMPUTED_VALUE"""),0.376) -> 0.376 | I15: =A15 -> 45839 | J15: =IF(ISBLANK(B15),SUM(B103:B105),SUM(B15:B17)) -> 907390592 | K15: =IF(ISBLANK(B15),SUM(B115:B117),SUM(B27:B29)) -> 694442208 | L15: =(J15-K15)/K15 -> 0.30664666 | M15: =IF(ISBLANK(B15),SUM(B103:B114),SUM(B15:B26)) -> 3467411424 | N15: =IF(ISBLANK(B15),SUM(B115:B126),SUM(B27:B38)) -> 2517753040 | O15: =(M15-N15)/N15 -> 0.37718488 | P15: =L15-O15 -> -0.070538222 | Q15: =IF(P15>P16,"長短期YOY擴大","長短期YOY收斂") -> 長短期YOY收斂 | S15: =IF(ISBLANK(B15),AVERAGE(B103:B105),AVERAGE(B15:B17)) -> 3.0246353e+08 | T15: =IF(ISBLANK(B15),AVERAGE(B103:B114),AVERAGE(B15:B26)) -> 288950952 | U15: =S15-T15 -> 13512579 | V15: =IF(U15>S16,"長短期營收擴大","長短期營收收斂") -> 長短期營收擴大
A16: =IFERROR(__xludf.DUMMYFUNCTION("""COMPUTED_VALUE"""),45809) -> 45809 | B16: =IFERROR(__xludf.DUMMYFUNCTION("""COMPUTED_VALUE"""),263708992) -> 263708992 | C16: =IFERROR(__xludf.DUMMYFUNCTION("""COMPUTED_VALUE"""),207868704) -> 207868704 | D16: =IFERROR(__xludf.DUMMYFUNCTION("""COMPUTED_VALUE"""),-0.177) -> -0.177 | E16: =IFERROR(__xludf.DUMMYFUNCTION("""COMPUTED_VALUE"""),0.269) -> 0.269 | F16: =IFERROR(__xludf.DUMMYFUNCTION("""COMPUTED_VALUE"""),1773046016) -> 1773046016 | G16: =IFERROR(__xludf.DUMMYFUNCTION("""COMPUTED_VALUE"""),1266153984) -> 1266153984 | H16: =IFERROR(__xludf.DUMMYFUNCTION("""COMPUTED_VALUE"""),0.4) -> 0.4
A17: =IFERROR(__xludf.DUMMYFUNCTION("""COMPUTED_VALUE"""),45778) -> 45778 | B17: =IFERROR(__xludf.DUMMYFUNCTION("""COMPUTED_VALUE"""),320515904) -> 320515904 | C17: =IFERROR(__xludf.DUMMYFUNCTION("""COMPUTED_VALUE"""),229620400) -> 229620400 | D17: =IFERROR(__xludf.DUMMYFUNCTION("""COMPUTED_VALUE"""),-0.083) -> -0.083 | E17: =IFERROR(__xludf.DUMMYFUNCTION("""COMPUTED_VALUE"""),0.396) -> 0.396 | F17: =IFERROR(__xludf.DUMMYFUNCTION("""COMPUTED_VALUE"""),1509336960) -> 1509336960 | G17: =IFERROR(__xludf.DUMMYFUNCTION("""COMPUTED_VALUE"""),1058286016) -> 1058286016 | H17: =IFERROR(__xludf.DUMMYFUNCTION("""COMPUTED_VALUE"""),0.426) -> 0.426
A18: =IFERROR(__xludf.DUMMYFUNCTION("""COMPUTED_VALUE"""),45748) -> 45748 | B18: =IFERROR(__xludf.DUMMYFUNCTION("""COMPUTED_VALUE"""),349566912) -> 349566912 | C18: =IFERROR(__xludf.DUMMYFUNCTION("""COMPUTED_VALUE"""),236021104) -> 236021104 | D18: =IFERROR(__xludf.DUMMYFUNCTION("""COMPUTED_VALUE"""),0.222) -> 0.222 | E18: =IFERROR(__xludf.DUMMYFUNCTION("""COMPUTED_VALUE"""),0.481) -> 0.481 | F18: =IFERROR(__xludf.DUMMYFUNCTION("""COMPUTED_VALUE"""),1188820992) -> 1188820992 | G18: =IFERROR(__xludf.DUMMYFUNCTION("""COMPUTED_VALUE"""),828665280) -> 828665280 | H18: =IFERROR(__xludf.DUMMYFUNCTION("""COMPUTED_VALUE"""),0.435) -> 0.435
A19: =IFERROR(__xludf.DUMMYFUNCTION("""COMPUTED_VALUE"""),45717) -> 45717 | B19: =IFERROR(__xludf.DUMMYFUNCTION("""COMPUTED_VALUE"""),285956800) -> 285956800 | C19: =IFERROR(__xludf.DUMMYFUNCTION("""COMPUTED_VALUE"""),195210800) -> 195210800 | D19: =IFERROR(__xludf.DUMMYFUNCTION("""COMPUTED_VALUE"""),0.1) -> 0.1 | E19: =IFERROR(__xludf.DUMMYFUNCTION("""COMPUTED_VALUE"""),0.465) -> 0.465 | F19: =IFERROR(__xludf.DUMMYFUNCTION("""COMPUTED_VALUE"""),839253632) -> 839253632 | G19: =IFERROR(__xludf.DUMMYFUNCTION("""COMPUTED_VALUE"""),592644224) -> 592644224 | H19: =IFERROR(__xludf.DUMMYFUNCTION("""COMPUTED_VALUE"""),0.416) -> 0.416
A20: =IFERROR(__xludf.DUMMYFUNCTION("""COMPUTED_VALUE"""),45689) -> 45689 | B20: =IFERROR(__xludf.DUMMYFUNCTION("""COMPUTED_VALUE"""),260008800) -> 260008800 | C20: =IFERROR(__xludf.DUMMYFUNCTION("""COMPUTED_VALUE"""),181648304) -> 181648304 | D20: =IFERROR(__xludf.DUMMYFUNCTION("""COMPUTED_VALUE"""),-0.113) -> -0.113 | E20: =IFERROR(__xludf.DUMMYFUNCTION("""COMPUTED_VALUE"""),0.431) -> 0.431 | F20: =IFERROR(__xludf.DUMMYFUNCTION("""COMPUTED_VALUE"""),553296768) -> 553296768 | G20: =IFERROR(__xludf.DUMMYFUNCTION("""COMPUTED_VALUE"""),397433408) -> 397433408 | H20: =IFERROR(__xludf.DUMMYFUNCTION("""COMPUTED_VALUE"""),0.392) -> 0.392
A21: =IFERROR(__xludf.DUMMYFUNCTION("""COMPUTED_VALUE"""),45658) -> 45658 | B21: =IFERROR(__xludf.DUMMYFUNCTION("""COMPUTED_VALUE"""),293288000) -> 293288000 | C21: =IFERROR(__xludf.DUMMYFUNCTION("""COMPUTED_VALUE"""),215785104) -> 215785104 | D21: =IFERROR(__xludf.DUMMYFUNCTION("""COMPUTED_VALUE"""),0.054) -> 0.054 | E21: =IFERROR(__xludf.DUMMYFUNCTION("""COMPUTED_VALUE"""),0.359) -> 0.359 | F21: =IFERROR(__xludf.DUMMYFUNCTION("""COMPUTED_VALUE"""),293288000) -> 293288000 | G21: =IFERROR(__xludf.DUMMYFUNCTION("""COMPUTED_VALUE"""),215785104) -> 215785104 | H21: =IFERROR(__xludf.DUMMYFUNCTION("""COMPUTED_VALUE"""),0.359) -> 0.359
A22: =IFERROR(__xludf.DUMMYFUNCTION("""COMPUTED_VALUE"""),45627) -> 45627 | B22: =IFERROR(__xludf.DUMMYFUNCTION("""COMPUTED_VALUE"""),278163104) -> 278163104 | C22: =IFERROR(__xludf.DUMMYFUNCTION("""COMPUTED_VALUE"""),176299904) -> 176299904 | D22: =IFERROR(__xludf.DUMMYFUNCTION("""COMPUTED_VALUE"""),0.008) -> 0.008 | E22: =IFERROR(__xludf.DUMMYFUNCTION("""COMPUTED_VALUE"""),0.578) -> 0.578 | F22: =IFERROR(__xludf.DUMMYFUNCTION("""COMPUTED_VALUE"""),2894308096) -> 2894308096 | G22: =IFERROR(__xludf.DUMMYFUNCTION("""COMPUTED_VALUE"""),2161735936) -> 2161735936 | H22: =IFERROR(__xludf.DUMMYFUNCTION("""COMPUTED_VALUE"""),0.339) -> 0.339
A23: =IFERROR(__xludf.DUMMYFUNCTION("""COMPUTED_VALUE"""),45597) -> 45597 | B23: =IFERROR(__xludf.DUMMYFUNCTION("""COMPUTED_VALUE"""),276058400) -> 276058400 | C23: =IFERROR(__xludf.DUMMYFUNCTION("""COMPUTED_VALUE"""),206026208) -> 206026208 | D23: =IFERROR(__xludf.DUMMYFUNCTION("""COMPUTED_VALUE"""),-0.121) -> -0.121 | E23: =IFERROR(__xludf.DUMMYFUNCTION("""COMPUTED_VALUE"""),0.34) -> 0.34 | F23: =IFERROR(__xludf.DUMMYFUNCTION("""COMPUTED_VALUE"""),2616144896) -> 2616144896 | G23: =IFERROR(__xludf.DUMMYFUNCTION("""COMPUTED_VALUE"""),1985436032) -> 1985436032 | H23: =IFERROR(__xludf.DUMMYFUNCTION("""COMPUTED_VALUE"""),0.318) -> 0.318
A24: =IFERROR(__xludf.DUMMYFUNCTION("""COMPUTED_VALUE"""),45566) -> 45566 | B24: =IFERROR(__xludf.DUMMYFUNCTION("""COMPUTED_VALUE"""),314239712) -> 314239712 | C24: =IFERROR(__xludf.DUMMYFUNCTION("""COMPUTED_VALUE"""),243202800) -> 243202800 | D24: =IFERROR(__xludf.DUMMYFUNCTION("""COMPUTED_VALUE"""),0.248) -> 0.248 | E24: =IFERROR(__xludf.DUMMYFUNCTION("""COMPUTED_VALUE"""),0.292) -> 0.292 | F24: =IFERROR(__xludf.DUMMYFUNCTION("""COMPUTED_VALUE"""),2340086016) -> 2340086016 | G24: =IFERROR(__xludf.DUMMYFUNCTION("""COMPUTED_VALUE"""),1779410048) -> 1779410048 | H24: =IFERROR(__xludf.DUMMYFUNCTION("""COMPUTED_VALUE"""),0.315) -> 0.315
A25: =IFERROR(__xludf.DUMMYFUNCTION("""COMPUTED_VALUE"""),45536) -> 45536 | B25: =IFERROR(__xludf.DUMMYFUNCTION("""COMPUTED_VALUE"""),251872704) -> 251872704 | C25: =IFERROR(__xludf.DUMMYFUNCTION("""COMPUTED_VALUE"""),180430304) -> 180430304 | D25: =IFERROR(__xludf.DUMMYFUNCTION("""COMPUTED_VALUE"""),0.004) -> 0.004 | E25: =IFERROR(__xludf.DUMMYFUNCTION("""COMPUTED_VALUE"""),0.396) -> 0.396 | F25: =IFERROR(__xludf.DUMMYFUNCTION("""COMPUTED_VALUE"""),2025847040) -> 2025847040 | G25: =IFERROR(__xludf.DUMMYFUNCTION("""COMPUTED_VALUE"""),1536206976) -> 1536206976 | H25: =IFERROR(__xludf.DUMMYFUNCTION("""COMPUTED_VALUE"""),0.319) -> 0.319
A26: =IFERROR(__xludf.DUMMYFUNCTION("""COMPUTED_VALUE"""),45505) -> 45505 | B26: =IFERROR(__xludf.DUMMYFUNCTION("""COMPUTED_VALUE"""),250866400) -> 250866400 | C26: =IFERROR(__xludf.DUMMYFUNCTION("""COMPUTED_VALUE"""),188686304) -> 188686304 | D26: =IFERROR(__xludf.DUMMYFUNCTION("""COMPUTED_VALUE"""),-0.024) -> -0.024 | E26: =IFERROR(__xludf.DUMMYFUNCTION("""COMPUTED_VALUE"""),0.33) -> 0.33 | F26: =IFERROR(__xludf.DUMMYFUNCTION("""COMPUTED_VALUE"""),1773974016) -> 1773974016 | G26: =IFERROR(__xludf.DUMMYFUNCTION("""COMPUTED_VALUE"""),1355777024) -> 1355777024 | H26: =IFERROR(__xludf.DUMMYFUNCTION("""COMPUTED_VALUE"""),0.308) -> 0.308
A27: =IFERROR(__xludf.DUMMYFUNCTION("""COMPUTED_VALUE"""),45474) -> 45474 | B27: =IFERROR(__xludf.DUMMYFUNCTION("""COMPUTED_VALUE"""),256953104) -> 256953104 | C27: =IFERROR(__xludf.DUMMYFUNCTION("""COMPUTED_VALUE"""),177616192) -> 177616192 | D27: =IFERROR(__xludf.DUMMYFUNCTION("""COMPUTED_VALUE"""),0.236) -> 0.236 | E27: =IFERROR(__xludf.DUMMYFUNCTION("""COMPUTED_VALUE"""),0.447) -> 0.447 | F27: =IFERROR(__xludf.DUMMYFUNCTION("""COMPUTED_VALUE"""),1523106944) -> 1523106944 | G27: =IFERROR(__xludf.DUMMYFUNCTION("""COMPUTED_VALUE"""),1167090048) -> 1167090048 | H27: =IFERROR(__xludf.DUMMYFUNCTION("""COMPUTED_VALUE"""),0.305) -> 0.305
A28: =IFERROR(__xludf.DUMMYFUNCTION("""COMPUTED_VALUE"""),45444) -> 45444 | B28: =IFERROR(__xludf.DUMMYFUNCTION("""COMPUTED_VALUE"""),207868704) -> 207868704 | C28: =IFERROR(__xludf.DUMMYFUNCTION("""COMPUTED_VALUE"""),156404192) -> 156404192 | D28: =IFERROR(__xludf.DUMMYFUNCTION("""COMPUTED_VALUE"""),-0.095) -> -0.095 | E28: =IFERROR(__xludf.DUMMYFUNCTION("""COMPUTED_VALUE"""),0.329) -> 0.329 | F28: =IFERROR(__xludf.DUMMYFUNCTION("""COMPUTED_VALUE"""),1266153984) -> 1266153984 | G28: =IFERROR(__xludf.DUMMYFUNCTION("""COMPUTED_VALUE"""),989474176) -> 989474176 | H28: =IFERROR(__xludf.DUMMYFUNCTION("""COMPUTED_VALUE"""),0.28) -> 0.28
A29: =IFERROR(__xludf.DUMMYFUNCTION("""COMPUTED_VALUE"""),45413) -> 45413 | B29: =IFERROR(__xludf.DUMMYFUNCTION("""COMPUTED_VALUE"""),229620400) -> 229620400 | C29: =IFERROR(__xludf.DUMMYFUNCTION("""COMPUTED_VALUE"""),176537296) -> 176537296 | D29: =IFERROR(__xludf.DUMMYFUNCTION("""COMPUTED_VALUE"""),-0.027) -> -0.027 | E29: =IFERROR(__xludf.DUMMYFUNCTION("""COMPUTED_VALUE"""),0.301) -> 0.301 | F29: =IFERROR(__xludf.DUMMYFUNCTION("""COMPUTED_VALUE"""),1058286016) -> 1058286016 | G29: =IFERROR(__xludf.DUMMYFUNCTION("""COMPUTED_VALUE"""),833070080) -> 833070080 | H29: =IFERROR(__xludf.DUMMYFUNCTION("""COMPUTED_VALUE"""),0.27) -> 0.27
A30: =IFERROR(__xludf.DUMMYFUNCTION("""COMPUTED_VALUE"""),45383) -> 45383 | B30: =IFERROR(__xludf.DUMMYFUNCTION("""COMPUTED_VALUE"""),236021104) -> 236021104 | C30: =IFERROR(__xludf.DUMMYFUNCTION("""COMPUTED_VALUE"""),147899696) -> 147899696 | D30: =IFERROR(__xludf.DUMMYFUNCTION("""COMPUTED_VALUE"""),0.209) -> 0.209 | E30: =IFERROR(__xludf.DUMMYFUNCTION("""COMPUTED_VALUE"""),0.596) -> 0.596 | F30: =IFERROR(__xludf.DUMMYFUNCTION("""COMPUTED_VALUE"""),828665280) -> 828665280 | G30: =IFERROR(__xludf.DUMMYFUNCTION("""COMPUTED_VALUE"""),656532672) -> 656532672 | H30: =IFERROR(__xludf.DUMMYFUNCTION("""COMPUTED_VALUE"""),0.262) -> 0.262
A31: =IFERROR(__xludf.DUMMYFUNCTION("""COMPUTED_VALUE"""),45352) -> 45352 | B31: =IFERROR(__xludf.DUMMYFUNCTION("""COMPUTED_VALUE"""),195210800) -> 195210800 | C31: =IFERROR(__xludf.DUMMYFUNCTION("""COMPUTED_VALUE"""),145408304) -> 145408304 | D31: =IFERROR(__xludf.DUMMYFUNCTION("""COMPUTED_VALUE"""),0.075) -> 0.075 | E31: =IFERROR(__xludf.DUMMYFUNCTION("""COMPUTED_VALUE"""),0.343) -> 0.343 | F31: =IFERROR(__xludf.DUMMYFUNCTION("""COMPUTED_VALUE"""),592644224) -> 592644224 | G31: =IFERROR(__xludf.DUMMYFUNCTION("""COMPUTED_VALUE"""),508632992) -> 508632992 | H31: =IFERROR(__xludf.DUMMYFUNCTION("""COMPUTED_VALUE"""),0.165) -> 0.165
A32: =IFERROR(__xludf.DUMMYFUNCTION("""COMPUTED_VALUE"""),45323) -> 45323 | B32: =IFERROR(__xludf.DUMMYFUNCTION("""COMPUTED_VALUE"""),181648304) -> 181648304 | C32: =IFERROR(__xludf.DUMMYFUNCTION("""COMPUTED_VALUE"""),163174096) -> 163174096 | D32: =IFERROR(__xludf.DUMMYFUNCTION("""COMPUTED_VALUE"""),-0.158) -> -0.158 | E32: =IFERROR(__xludf.DUMMYFUNCTION("""COMPUTED_VALUE"""),0.113) -> 0.113 | F32: =IFERROR(__xludf.DUMMYFUNCTION("""COMPUTED_VALUE"""),397433408) -> 397433408 | G32: =IFERROR(__xludf.DUMMYFUNCTION("""COMPUTED_VALUE"""),363224608) -> 363224608 | H32: =IFERROR(__xludf.DUMMYFUNCTION("""COMPUTED_VALUE"""),0.094) -> 0.094
A33: =IFERROR(__xludf.DUMMYFUNCTION("""COMPUTED_VALUE"""),45292) -> 45292 | B33: =IFERROR(__xludf.DUMMYFUNCTION("""COMPUTED_VALUE"""),215785104) -> 215785104 | C33: =IFERROR(__xludf.DUMMYFUNCTION("""COMPUTED_VALUE"""),200050496) -> 200050496 | D33: =IFERROR(__xludf.DUMMYFUNCTION("""COMPUTED_VALUE"""),0.224) -> 0.224 | E33: =IFERROR(__xludf.DUMMYFUNCTION("""COMPUTED_VALUE"""),0.079) -> 0.079 | F33: =IFERROR(__xludf.DUMMYFUNCTION("""COMPUTED_VALUE"""),215785104) -> 215785104 | G33: =IFERROR(__xludf.DUMMYFUNCTION("""COMPUTED_VALUE"""),200050496) -> 200050496 | H33: =IFERROR(__xludf.DUMMYFUNCTION("""COMPUTED_VALUE"""),0.079) -> 0.079
A34: =IFERROR(__xludf.DUMMYFUNCTION("""COMPUTED_VALUE"""),45261) -> 45261 | B34: =IFERROR(__xludf.DUMMYFUNCTION("""COMPUTED_VALUE"""),176299904) -> 176299904 | C34: =IFERROR(__xludf.DUMMYFUNCTION("""COMPUTED_VALUE"""),192560192) -> 192560192 | D34: =IFERROR(__xludf.DUMMYFUNCTION("""COMPUTED_VALUE"""),-0.144) -> -0.144 | E34: =IFERROR(__xludf.DUMMYFUNCTION("""COMPUTED_VALUE"""),-0.084) -> -0.084 | F34: =IFERROR(__xludf.DUMMYFUNCTION("""COMPUTED_VALUE"""),2161735936) -> 2161735936 | G34: =IFERROR(__xludf.DUMMYFUNCTION("""COMPUTED_VALUE"""),2263890944) -> 2263890944 | H34: =IFERROR(__xludf.DUMMYFUNCTION("""COMPUTED_VALUE"""),-0.045) -> -0.045
A35: =IFERROR(__xludf.DUMMYFUNCTION("""COMPUTED_VALUE"""),45231) -> 45231 | B35: =IFERROR(__xludf.DUMMYFUNCTION("""COMPUTED_VALUE"""),206026208) -> 206026208 | C35: =IFERROR(__xludf.DUMMYFUNCTION("""COMPUTED_VALUE"""),222706000) -> 222706000 | D35: =IFERROR(__xludf.DUMMYFUNCTION("""COMPUTED_VALUE"""),-0.153) -> -0.153 | E35: =IFERROR(__xludf.DUMMYFUNCTION("""COMPUTED_VALUE"""),-0.075) -> -0.075 | F35: =IFERROR(__xludf.DUMMYFUNCTION("""COMPUTED_VALUE"""),1985436032) -> 1985436032 | G35: =IFERROR(__xludf.DUMMYFUNCTION("""COMPUTED_VALUE"""),2071330944) -> 2071330944 | H35: =IFERROR(__xludf.DUMMYFUNCTION("""COMPUTED_VALUE"""),-0.041) -> -0.041
A36: =IFERROR(__xludf.DUMMYFUNCTION("""COMPUTED_VALUE"""),45200) -> 45200 | B36: =IFERROR(__xludf.DUMMYFUNCTION("""COMPUTED_VALUE"""),243202800) -> 243202800 | C36: =IFERROR(__xludf.DUMMYFUNCTION("""COMPUTED_VALUE"""),210265600) -> 210265600 | D36: =IFERROR(__xludf.DUMMYFUNCTION("""COMPUTED_VALUE"""),0.348) -> 0.348 | E36: =IFERROR(__xludf.DUMMYFUNCTION("""COMPUTED_VALUE"""),0.157) -> 0.157 | F36: =IFERROR(__xludf.DUMMYFUNCTION("""COMPUTED_VALUE"""),1779410048) -> 1779410048 | G36: =IFERROR(__xludf.DUMMYFUNCTION("""COMPUTED_VALUE"""),1848625024) -> 1848625024 | H36: =IFERROR(__xludf.DUMMYFUNCTION("""COMPUTED_VALUE"""),-0.037) -> -0.037
A37: =IFERROR(__xludf.DUMMYFUNCTION("""COMPUTED_VALUE"""),45170) -> 45170 | B37: =IFERROR(__xludf.DUMMYFUNCTION("""COMPUTED_VALUE"""),180430304) -> 180430304 | C37: =IFERROR(__xludf.DUMMYFUNCTION("""COMPUTED_VALUE"""),208247696) -> 208247696 | D37: =IFERROR(__xludf.DUMMYFUNCTION("""COMPUTED_VALUE"""),-0.044) -> -0.044 | E37: =IFERROR(__xludf.DUMMYFUNCTION("""COMPUTED_VALUE"""),-0.134) -> -0.134 | F37: =IFERROR(__xludf.DUMMYFUNCTION("""COMPUTED_VALUE"""),1536206976) -> 1536206976 | G37: =IFERROR(__xludf.DUMMYFUNCTION("""COMPUTED_VALUE"""),1638359040) -> 1638359040 | H37: =IFERROR(__xludf.DUMMYFUNCTION("""COMPUTED_VALUE"""),-0.062) -> -0.062
A38: =IFERROR(__xludf.DUMMYFUNCTION("""COMPUTED_VALUE"""),45139) -> 45139 | B38: =IFERROR(__xludf.DUMMYFUNCTION("""COMPUTED_VALUE"""),188686304) -> 188686304 | C38: =IFERROR(__xludf.DUMMYFUNCTION("""COMPUTED_VALUE"""),218132400) -> 218132400 | D38: =IFERROR(__xludf.DUMMYFUNCTION("""COMPUTED_VALUE"""),0.062) -> 0.062 | E38: =IFERROR(__xludf.DUMMYFUNCTION("""COMPUTED_VALUE"""),-0.135) -> -0.135 | F38: =IFERROR(__xludf.DUMMYFUNCTION("""COMPUTED_VALUE"""),1355777024) -> 1355777024 | G38: =IFERROR(__xludf.DUMMYFUNCTION("""COMPUTED_VALUE"""),1430112000) -> 1430112000 | H38: =IFERROR(__xludf.DUMMYFUNCTION("""COMPUTED_VALUE"""),-0.052) -> -0.052
O42: 月份 | P42: =YEAR(A3) -> 2026 | Q42: =YEAR(A3)-1 -> 2025 | R42: =YEAR(A3)-2 -> 2024
A43: =IFERROR(__xludf.DUMMYFUNCTION("IMPORTHTML(SUBSTITUTE(""https://histock.tw/stock/financial.aspx?no=股票代碼&t=5&st=4&q=2"", ""股票代碼"",'股價預估'!E1),""table"",0)"),"年度/季別") -> 年度/季別 | B43: =IFERROR(__xludf.DUMMYFUNCTION("""COMPUTED_VALUE"""),"營收年增率") -> 營收年增率 | C43: =IFERROR(__xludf.DUMMYFUNCTION("""COMPUTED_VALUE"""),"近4季營收年增率") -> 近4季營收年增率 | D43: =IFERROR(__xludf.DUMMYFUNCTION("""COMPUTED_VALUE"""),"年度/季別") -> 年度/季別 | E43: =IFERROR(__xludf.DUMMYFUNCTION("""COMPUTED_VALUE"""),"營收年增率") -> 營收年增率 | F43: =IFERROR(__xludf.DUMMYFUNCTION("""COMPUTED_VALUE"""),"近4季營收年增率") -> 近4季營收年增率 | O43: =MONTH(A3) -> 7 | P43: =B3 -> 467580544 | Q43: =B15 -> 323165696 | R43: =B27 -> 256953104
...

Sheet 毛利率&業外
A1: =IFERROR(__xludf.DUMMYFUNCTION("IMPORTHTML(SUBSTITUTE(""https://fubon-ebrokerdj.fbs.com.tw/z/zc/zce/zce_股票代碼.djhtm"", ""股票代碼"",'股價預估'!E1),""table"",0)"),"台積電(2330)獲利能力分析 季報 單位：百萬") -> 台積電(2330)獲利能力分析 季報 單位：百萬 | N1: ="★ 最新毛利率 "&TEXT(E4,"0.0%")&" 營益率 "&TEXT(G4,"0.0%")&" 業外占比 "&TEXT(L4,"0.0%") -> ★ 最新毛利率 67.7% 營益率 60.3% 業外占比 11.1%
A3: =IFERROR(__xludf.DUMMYFUNCTION("""COMPUTED_VALUE"""),"季別") -> 季別 | B3: =IFERROR(__xludf.DUMMYFUNCTION("""COMPUTED_VALUE"""),"營業收入") -> 營業收入 | C3: =IFERROR(__xludf.DUMMYFUNCTION("""COMPUTED_VALUE"""),"營業成本") -> 營業成本 | D3: =IFERROR(__xludf.DUMMYFUNCTION("""COMPUTED_VALUE"""),"營業毛利") -> 營業毛利 | E3: =IFERROR(__xludf.DUMMYFUNCTION("""COMPUTED_VALUE"""),"毛利率") -> 毛利率 | F3: =IFERROR(__xludf.DUMMYFUNCTION("""COMPUTED_VALUE"""),"營業利益") -> 營業利益 | G3: =IFERROR(__xludf.DUMMYFUNCTION("""COMPUTED_VALUE"""),"營益率") -> 營益率 | H3: =IFERROR(__xludf.DUMMYFUNCTION("""COMPUTED_VALUE"""),"業外收支") -> 業外收支 | I3: =IFERROR(__xludf.DUMMYFUNCTION("""COMPUTED_VALUE"""),"稅前淨利") -> 稅前淨利 | J3: =IFERROR(__xludf.DUMMYFUNCTION("""COMPUTED_VALUE"""),"稅後淨利") -> 稅後淨利 | K3: =IFERROR(__xludf.DUMMYFUNCTION("""COMPUTED_VALUE"""),"EPS(元)") -> EPS(元) | L3: 業外占比
A4: =IFERROR(__xludf.DUMMYFUNCTION("""COMPUTED_VALUE"""),"115.2Q") -> 115.2Q | B4: =IFERROR(__xludf.DUMMYFUNCTION("""COMPUTED_VALUE"""),1270380) -> 1270380 | C4: =IFERROR(__xludf.DUMMYFUNCTION("""COMPUTED_VALUE"""),410070) -> 410070 | D4: =IFERROR(__xludf.DUMMYFUNCTION("""COMPUTED_VALUE"""),860311) -> 860311 | E4: =IFERROR(__xludf.DUMMYFUNCTION("""COMPUTED_VALUE"""),0.6772) -> 0.6772 | F4: =IFERROR(__xludf.DUMMYFUNCTION("""COMPUTED_VALUE"""),766603) -> 766603 | G4: =IFERROR(__xludf.DUMMYFUNCTION("""COMPUTED_VALUE"""),0.6034) -> 0.6034 | H4: =IFERROR(__xludf.DUMMYFUNCTION("""COMPUTED_VALUE"""),95827) -> 95827 | I4: =IFERROR(__xludf.DUMMYFUNCTION("""COMPUTED_VALUE"""),862430) -> 862430 | J4: =IFERROR(__xludf.DUMMYFUNCTION("""COMPUTED_VALUE"""),706562) -> 706562 | K4: =IFERROR(__xludf.DUMMYFUNCTION("""COMPUTED_VALUE"""),27.25) -> 27.25 | L4: =H4/I4 -> 0.11111279 | N4: =AVERAGE(L4:L7) -> 0.061594344
A5: =IFERROR(__xludf.DUMMYFUNCTION("""COMPUTED_VALUE"""),"115.1Q") -> 115.1Q | B5: =IFERROR(__xludf.DUMMYFUNCTION("""COMPUTED_VALUE"""),1134103) -> 1134103 | C5: =IFERROR(__xludf.DUMMYFUNCTION("""COMPUTED_VALUE"""),382808) -> 382808 | D5: =IFERROR(__xludf.DUMMYFUNCTION("""COMPUTED_VALUE"""),751295) -> 751295 | E5: =IFERROR(__xludf.DUMMYFUNCTION("""COMPUTED_VALUE"""),0.6625) -> 0.6625 | F5: =IFERROR(__xludf.DUMMYFUNCTION("""COMPUTED_VALUE"""),658966) -> 658966 | G5: =IFERROR(__xludf.DUMMYFUNCTION("""COMPUTED_VALUE"""),0.581) -> 0.581 | H5: =IFERROR(__xludf.DUMMYFUNCTION("""COMPUTED_VALUE"""),28834) -> 28834 | I5: =IFERROR(__xludf.DUMMYFUNCTION("""COMPUTED_VALUE"""),687800) -> 687800 | J5: =IFERROR(__xludf.DUMMYFUNCTION("""COMPUTED_VALUE"""),572480) -> 572480 | K5: =IFERROR(__xludf.DUMMYFUNCTION("""COMPUTED_VALUE"""),22.08) -> 22.08 | L5: =H5/I5 -> 0.04192207
